Workbook

Sheet Geometry Summary
A1: Abbreviation | B1: Building Type | C1: Shape | D1: Number of Floors | E1: Aspect Ratio | F1: Zone Height_1 | G1: Zone Height_2 | H1: Zone Height_3 | I1: Plenum Height | J1: Floor to Floor Height (feet) | K1: Floor to Ceiling Height (feet)
A2: Asm | B2: Assembly | C2: #VALUE! | D2: 1 | E2: 1 | F2: 12.000578 | G2: na | H2: na | I2: 3.0001456 | J2: =F2 -> 12.000578 | K2: =J2+I2 -> 15.000723
A3: ECC | B3: Education - Community College | C3: #VALUE! | D3: 3 | E3: 5.7 | F3: 9.0004351 | G3: 13.000638 | H3: na | I3: 4.0002044 | J3: 9 / 13 | K3: 13 / 17
A4: EPr | B4: Education - Primary School | C4: #VALUE! | D4: 1 | E4: 2 | F4: 9.0004364 | G4: 12.000591 | H4: na | I4: 3.0001461 | J4: 9 / 12 | K4: 12 / 15
A5: ERC | B5: Education - Relocatable Classroom | C5: #VALUE! | D5: 1 | E5: 1.7 | F5: 9.0004473 | G5: na | H5: na | I5: 3.0001456 | J5: =F5 -> 9.0004473 | K5: =J5+I5 -> 12.000593
A6: ESe | B6: Education - Secondary School | C6: #VALUE! | D6: 2 | E6: 2.5/1.0 | F6: 9.0004492 | G6: 13.000632 | H6: na | I6: 4.0001946 | J6: 9 / 13 | K6: 13 / 17
A7: EUn | B7: Education - University | C7: #VALUE! | D7: 4 | E7: 2.0/15.0 | F7: 10.000492 | G7: 9.0004349 | H7: 14.000685 | I7: 4.0001957 | J7: 9 / 10 / 14 | K7: 13 / 14 / 18
A8: Fin | B8: Financial buildings, incl. banks | C8: #VALUE! | D8: 1 | E8: 1 | F8: 11.000511 | G8: na | H8: na | I8: na | J8: =F8 -> 11.000511 | K8: =J8 -> 11.000511
A9: Gro | B9: Grocery | C9: #VALUE! | D9: 1 | E9: 1 | F9: 25.001203 | G9: na | H9: na | I9: na | J9: =F9 -> 25.001203 | K9: =J9 -> 25.001203
A10: Hsp | B10: Health/Medical - Hospital | C10: #VALUE! | D10: 3 | E10: 1 | F10: 10.007046 | G10: 12.992746 | H10: na | I10: 2.985712 | J10: 10 / 13 | K10: 13 / 16
A11: Htl | B11: Lodging - Hotel | C11: #VALUE! | D11: 4 | E11: 6.6 | F11: 8.0003806 | G11: 10.500488 | H11: na | I11: 1.500073 | J11: 8 / 11 | K11: 10 / 12
A12: Lib | B12: Libraries | C12: #VALUE! | D12: 1 | E12: 1 | F12: 13.00063 | G12: na | H12: na | I12: na | J12: =F12 -> 13.00063 | K12: =J12 -> 13.00063
A13: MBT | B13: Manufacturing Biotech | C13: #VALUE! | D13: 1 | E13: 6 | F13: 9.0004452 | G13: na | H13: na | I13: 6.0003317 | J13: =F13 -> 9.0004452 | K13: =J13+I13 -> 15.000777
A14: MLI | B14: Manufacturing Light Industrial | C14: #VALUE! | D14: 1 | E14: 1 | F14: 35.001709 | G14: na | H14: na | I14: na | J14: =F14 -> 35.001709 | K14: =J14 -> 35.001709
A15: Mtl | B15: Lodging - Motel | C15: #VALUE! | D15: 2 | E15: 5.1 | F15: 9.0004353 | G15: na | H15: na | I15: na | J15: =F15 -> 9.0004353 | K15: =J15 -> 9.0004353
A16: Nrs | B16: Health/Medical - Nursing Home | C16: #VALUE! | D16: 2 | E16: 10.3 | F16: 12.998582 | G16: 9.0004507 | H16: na | I16: 4.0055319 | J16: 9 / 13 | K16: 13 / 17
A17: OfL | B17: Office - Large | C17: #VALUE! | D17: 3 | E17: 1.5 | F17: 9.0004157 | G17: na | H17: na | I17: 3.0001406 | J17: =F17 -> 9.0004157 | K17: =J17+I17 -> 12.000556
A18: OfS | B18: Office - Small | C18: #VALUE! | D18: 2 | E18: 1.5 | F18: 9.0004138 | G18: na | H18: na | I18: 3.0001401 | J18: =F18 -> 9.0004138 | K18: =J18+I18 -> 12.000554
A19: Rel | B19: Religious assembly buildings | C19: #VALUE! | D19: 1 | E19: 2.5 | F19: 37.501823 | G19: 15.0007 | H19: na | I19: na | J19: 38 / 15 | K19: 38 / 15
A20: RFF | B20: Restaurant - Fast-Food | C20: #VALUE! | D20: 1 | E20: 1 | F20: 10.000526 | G20: na | H20: na | I20: 3.0001627 | J20: =F20 -> 10.000526 | K20: =J20+I20 -> 13.000689
A21: RSD | B21: Restaurant - Sit-Down | C21: #VALUE! | D21: 1 | E21: 1 | F21: 10.000487 | G21: na | H21: na | I21: 3.0001467 | J21: =F21 -> 10.000487 | K21: =J21+I21 -> 13.000634
A22: Rt3 | B22: Retail - Multistory Large | C22: #VALUE! | D22: 3 | E22: 1 | F22: 15.000732 | G22: na | H22: na | I22: 5.8001832 | J22: =F22 -> 15.000732 | K22: =J22+I22 -> 20.800916
A23: RtL | B23: Retail - Single-Story Large | C23: #VALUE! | D23: 1 | E23: 1 | F23: 20.500994 | G23: na | H23: na | I23: na | J23: =F23 -> 20.500994 | K23: =J23 -> 20.500994
A24: RtS | B24: Retail - Small | C24: #VALUE! | D24: 1 | E24: 1 | F24: 10.000506 | G24: na | H24: na | I24: 2.0001 | J24: =F24 -> 10.000506 | K24: =J24+I24 -> 12.000606
A25: SCn | B25: Storage - Conditioned | C25: #VALUE! | D25: 1 | E25: 1 | F25: 48.002341 | G25: na | H25: na | I25: na | J25: =F25 -> 48.002341 | K25: =J25 -> 48.002341
A26: SUn | B26: Storage - Unconditioned | C26: #VALUE! | D26: 1 | E26: 1 | F26: 48.002341 | G26: na | H26: na | I26: na | J26: =F26 -> 48.002341 | K26: =J26 -> 48.002341
A27: WRf | B27: Warehouse - Refrigerated | C27: #VALUE! | D27: 1 | E27: 1 | F27: 48.002341 | G27: na | H27: na | I27: na | J27: =F27 -> 48.002341 | K27: =J27 -> 48.002341

Sheet Prototype
A1: TRC, Updated Febuary 2026
A2: =B4 -> Retail - Multistory Large
A3: Characteristic | B3: Value
A4: Building Type | B4: =Raw_building!A2 -> Retail - Multistory Large
A5: Building Category | B5: =Raw_building!B2 -> Nonresidential
A6: Vintages | B6: Two vintages: Existing and New Construction
A7: Shape | B7: =_xlfn.XLOOKUP( B4, 'Geometry Summary'!$B:$B, 'Geometry Summary'!$C:$C, "" ) -> #VALUE!
A8: Total Floor Area (ft²) | B8: =Zones!H33 -> 120011.7
A9: Aspect Ratio | B9: =_xlfn.XLOOKUP( B4, 'Geometry Summary'!$B:$B, 'Geometry Summary'!$E:$E, "" ) -> 1
A10: Number of Floors | B10: =_xlfn.XLOOKUP( B4, 'Geometry Summary'!$B:$B, 'Geometry Summary'!$D:$D, "" ) -> 3
A11: Roof Type | B11: =Raw_building!C2 -> Flat Roof
A12: Gross Window to Wall Ratio (%) | B12: =Raw_building!D2 -> 2
A13: Shading Geometry | B13: =_xlfn.TEXTJOIN("; ", TRUE, _xlfn.BYROW(Raw_shadinggeometry!A2:C7, _xlfn.LAMBDA(_xlpm.r, _xlfn.TEXTJOIN(", ", TRUE, _xlpm.r)))) -> No Shading
A14: Floor to Floor Height (feet) | B14: =_xlfn.XLOOKUP( B4, 'Geometry Summary'!$B:$B, 'Geometry Summary'!$J:$J, "" ) -> 15.000732
A15: Floor to Ceiling Height (feet) | B15: =_xlfn.XLOOKUP( B4, 'Geometry Summary'!$B:$B, 'Geometry Summary'!$K:$K, "" ) -> 20.800916
A16: Glazing Sill Height (feet) | B16: =AVERAGE(Raw_windowdimensionsillheight!D:D) -> 3

Sheet Notes
A1: Prototype Overview
A2: Name | B2: Description
A3: Asm | B3: Assembly
A4: ECC | B4: Education - Community College
A5: EPr | B5: Education - Primary School
A6: ERC | B6: Education - Relocatable Classroom
A7: ESe | B7: Education - Secondary School
A8: EUn | B8: Education - University
A9: Fin | B9: Financial buildings, incl. banks
A10: Gro | B10: Grocery
A11: Hsp | B11: Health/Medical - Hospital
A12: Htl | B12: Lodging - Hotel
A13: Lib | B13: Libraries
... A28: WRf | B28: Warehouse - Refrigerated
A31: Vintages
A32: Existing | B32: Weighted average of Title 24 requirements based on vintages from 1975 to 2022
A33: New Construction | B33: Title 24 2025
A36: Run Begin Day
A37: Begin Month | B37: Begin Day of Month | C37: Day of Week for Start Day
A38: =Raw_runbeginday!A2 -> 1 | B38: =Raw_runbeginday!B2 -> 1 | C38: =Raw_runbeginday!C2 -> Sunday
A41: Special Days
A42: Name | B42: Start Date | C42: Duration (days) | D42: Special Day Type
A43: =Raw_specialdays!A2 -> New Years Day | B43: =Raw_specialdays!B2 -> January 1 | C43: =Raw_specialdays!C2 -> 1 | D43: =Raw_specialdays!D2 -> Holiday
A44: =Raw_specialdays!A3 -> Veterans Day | B44: =Raw_specialdays!B3 -> November 11 | C44: =Raw_specialdays!C3 -> 1 | D44: =Raw_specialdays!D3 -> Holiday
A45: =Raw_specialdays!A4 -> Christmas | B45: =Raw_specialdays!B4 -> December 25 | C45: =Raw_specialdays!C4 -> 1 | D45: =Raw_specialdays!D4 -> Holiday
A46: =Raw_specialdays!A5 -> Independence Day | B46: =Raw_specialdays!B5 -> July 4 | C46: =Raw_specialdays!C5 -> 1 | D46: =Raw_specialdays!D5 -> Holiday
A47: =Raw_specialdays!A6 -> MLK Day | B47: =Raw_specialdays!B6 -> 3rd Monday in January | C47: =Raw_specialdays!C6 -> 1 | D47: =Raw_specialdays!D6 -> Holiday
A48: =Raw_specialdays!A7 -> Presidents Day | B48: =Raw_specialdays!B7 -> 3rd Monday in February | C48: =Raw_specialdays!C7 -> 1 | D48: =Raw_specialdays!D7 -> Holiday
A49: =Raw_specialdays!A8 -> Memorial Day | B49: =Raw_specialdays!B8 -> Last Monday in May | C49: =Raw_specialdays!C8 -> 1 | D49: =Raw_specialdays!D8 -> Holiday
A50: =Raw_specialdays!A9 -> Labor Day | B50: =Raw_specialdays!B9 -> 1st Monday in September | C50: =Raw_specialdays!C9 -> 1 | D50: =Raw_specialdays!D9 -> Holiday
A51: =Raw_specialdays!A10 -> Columbus Day | B51: =Raw_specialdays!B10 -> 2nd Monday in October | C51: =Raw_specialdays!C10 -> 1 | D51: =Raw_specialdays!D10 -> Holiday
A52: =Raw_specialdays!A11 -> Thanksgiving | B52: =Raw_specialdays!B11 -> 4th Thursday in November | C52: =Raw_specialdays!C11 -> 1 | D52: =Raw_specialdays!D11 -> Holiday

Sheet Raw_runbeginday
A1: Begin Month | B1: Begin Day of Month | C1: Day of Week for Start Day
A2: 1 | B2: 1 | C2: Sunday

Sheet Raw_specialdays
A1: Name | B1: Start Day | C1: Duration | D1: Special Day Type
A2: New Years Day | B2: January 1 | C2: 1 | D2: Holiday
A3: Veterans Day | B3: November 11 | C3: 1 | D3: Holiday
A4: Christmas | B4: December 25 | C4: 1 | D4: Holiday
A5: Independence Day | B5: July 4 | C5: 1 | D5: Holiday
A6: MLK Day | B6: 3rd Monday in January | C6: 1 | D6: Holiday
A7: Presidents Day | B7: 3rd Monday in February | C7: 1 | D7: Holiday
A8: Memorial Day | B8: Last Monday in May | C8: 1 | D8: Holiday
A9: Labor Day | B9: 1st Monday in September | C9: 1 | D9: Holiday
A10: Columbus Day | B10: 2nd Monday in October | C10: 1 | D10: Holiday
A11: Thanksgiving | B11: 4th Thursday in November | C11: 1 | D11: Holiday

Sheet Climate Zone
A1: Climate Zones - All Prototypes
A2: Climate Zone | B2: Representative City | C2: Weather File Name
A3: CZ01 | B3: Eureka | C3: CA_EUREKA_725940S_CZ2022.epw
A4: CZ02 | B4: Napa | C4: CA_NAPA-CO_724955S_CZ2022.epw
A5: CZ03 | B5: Oakland | C5: CA_OAKLAND-METRO-AP_724930S_CZ2022.epw
A6: CZ04 | B6: San Jose | C6: CA_SAN-JOSE-IAP_724945S_CZ2022.epw
A7: CZ05 | B7: Santa Maria | C7: CA_SANTA-MARIA-PUBLIC-AP_723940S_CZ2022.epw
A8: CZ06 | B8: Los Angeles | C8: CA_LOS-ANGELES-IAP_722950S_CZ2022.epw
A9: CZ07 | B9: San Diego-Lindbergh | C9: CA_SAN-DIEGO-LINDBERGH-FLD_722900S_CZ2022.epw
A10: CZ08 | B10: Long Beach-Daugherty | C10: CA_LONG-BEACH-DAUGHERTY-FLD_722970S_CZ2022.epw
A11: CZ09 | B11: Los Angeles | C11: CA_LOS-ANGELES-DOWNTOWN-USC_722874S_CZ2022.epw
A12: CZ10 | B12: Riverside | C12: CA_RIVERSIDE-MUNI_722869S_CZ2022.epw
A13: CZ11 | B13: Red Bluff | C13: CA_RED-BLUFF-MUNI-AP_725910S_CZ2022.epw
... A18: CZ16 | B18: Bishop | C18: CA_BISHOP-AP_724800S_CZ2022.epw
F25: Source: California Energy Commission, https://cecgis-caenergy.opendata.arcgis.com/datasets/CAEnergy::california-building-climate-zones/about

Sheet Zones
A1: ="Zone Summary - "&Prototype!A2 -> Zone Summary - Retail - Multistory Large
A2: Space | B2: Zone Name | C2: Conditioned [Y/N] | D2: Zone Type | E2: HVAC System Identifier (Main/Alternative/Customized) | F2: Schedule Identifier | G2: Area Fraction | H2: Area (Excluding Plenums and Crawl Space) (ft²) | I2: Volume (ft³) | J2: Multipliers | K2: People (Persons/1,000 ft²) | L2: Note
A3: =IF(TRIM(Raw_zonesummary!$A2)="Existing",Raw_zonesummary!B2,"") -> EL1 CORE PLNM (G.C10) | B3: =IF(TRIM(Raw_zonesummary!$A2)="Existing",Raw_zonesummary!C2,"") -> EL1 CORE PLNM (G.C10) | C3: =IF(TRIM(Raw_zonesummary!$A2)="Existing",Raw_zonesummary!D2,"") -> No | D3: =IF(TRIM(Raw_zonesummary!$A2)="Existing",Raw_zonesummary!P2,"") -> Plenum | E3: =IF(TRIM(Raw_zonesummary!$A2)="Existing",Raw_zonesummary!Q2,"") -> - | F3: =IF(TRIM(Raw_zonesummary!$A2)="Existing",Raw_zonesummary!R2,"") -> Plenum | G3: =IFERROR(H3*J3/H33,"") -> 0 | H3: =IF(TRIM(Raw_zonesummary!$A2)="Existing",Raw_zonesummary!E2,"") -> 0 | I3: =IF(TRIM(Raw_zonesummary!$A2)="Existing",Raw_zonesummary!I2,"") -> 167641.65 | J3: =IF(TRIM(Raw_zonesummary!$A2)="Existing",Raw_zonesummary!J2,"") -> 1 | K3: =IF(TRIM(Raw_zonesummary!$A2)="Existing",Raw_zonesummary!K2,"") -> 0
A4: =IF(TRIM(Raw_zonesummary!$A3)="Existing",Raw_zonesummary!B3,"") -> EL1 CORE PLNM (M.C20) | B4: =IF(TRIM(Raw_zonesummary!$A3)="Existing",Raw_zonesummary!C3,"") -> EL1 CORE PLNM (M.C20) | C4: =IF(TRIM(Raw_zonesummary!$A3)="Existing",Raw_zonesummary!D3,"") -> No | D4: =IF(TRIM(Raw_zonesummary!$A3)="Existing",Raw_zonesummary!P3,"") -> Plenum | E4: =IF(TRIM(Raw_zonesummary!$A3)="Existing",Raw_zonesummary!Q3,"") -> - | F4: =IF(TRIM(Raw_zonesummary!$A3)="Existing",Raw_zonesummary!R3,"") -> Plenum | G4: =IFERROR(H4*J4/H33,"") -> 0 | H4: =IF(TRIM(Raw_zonesummary!$A3)="Existing",Raw_zonesummary!E3,"") -> 0 | I4: =IF(TRIM(Raw_zonesummary!$A3)="Existing",Raw_zonesummary!I3,"") -> 167650.32 | J4: =IF(TRIM(Raw_zonesummary!$A3)="Existing",Raw_zonesummary!J3,"") -> 1 | K4: =IF(TRIM(Raw_zonesummary!$A3)="Existing",Raw_zonesummary!K3,"") -> 0
A5: =IF(TRIM(Raw_zonesummary!$A4)="Existing",Raw_zonesummary!B4,"") -> EL1 CORE PLNM (T.C30) | B5: =IF(TRIM(Raw_zonesummary!$A4)="Existing",Raw_zonesummary!C4,"") -> EL1 CORE PLNM (T.C30) | C5: =IF(TRIM(Raw_zonesummary!$A4)="Existing",Raw_zonesummary!D4,"") -> No | D5: =IF(TRIM(Raw_zonesummary!$A4)="Existing",Raw_zonesummary!P4,"") -> Plenum | E5: =IF(TRIM(Raw_zonesummary!$A4)="Existing",Raw_zonesummary!Q4,"") -> - | F5: =IF(TRIM(Raw_zonesummary!$A4)="Existing",Raw_zonesummary!R4,"") -> Plenum | G5: =IFERROR(H5*J5/H33,"") -> 0 | H5: =IF(TRIM(Raw_zonesummary!$A4)="Existing",Raw_zonesummary!E4,"") -> 0 | I5: =IF(TRIM(Raw_zonesummary!$A4)="Existing",Raw_zonesummary!I4,"") -> 167638.76 | J5: =IF(TRIM(Raw_zonesummary!$A4)="Existing",Raw_zonesummary!J4,"") -> 1 | K5: =IF(TRIM(Raw_zonesummary!$A4)="Existing",Raw_zonesummary!K4,"") -> 0
A6: =IF(TRIM(Raw_zonesummary!$A5)="Existing",Raw_zonesummary!B5,"") -> EL1 CORE SPC (G.C5) | B6: =IF(TRIM(Raw_zonesummary!$A5)="Existing",Raw_zonesummary!C5,"") -> EL1 CORE SPC (G.C5) | C6: =IF(TRIM(Raw_zonesummary!$A5)="Existing",Raw_zonesummary!D5,"") -> Yes | D6: =IF(TRIM(Raw_zonesummary!$A5)="Existing",Raw_zonesummary!P5,"") -> Retail_sales | E6: =IF(TRIM(Raw_zonesummary!$A5)="Existing",Raw_zonesummary!Q5,"") -> Main | F6: =IF(TRIM(Raw_zonesummary!$A5)="Existing",Raw_zonesummary!R5,"") -> Retail | G6: =IFERROR(H6*J6/H33,"") -> 0.24083335 | H6: =IF(TRIM(Raw_zonesummary!$A5)="Existing",Raw_zonesummary!E5,"") -> 28902.82 | I6: =IF(TRIM(Raw_zonesummary!$A5)="Existing",Raw_zonesummary!I5,"") -> 433563.47 | J6: =IF(TRIM(Raw_zonesummary!$A5)="Existing",Raw_zonesummary!J5,"") -> 1 | K6: =IF(TRIM(Raw_zonesummary!$A5)="Existing",Raw_zonesummary!K5,"") -> 8.33
A7: =IF(TRIM(Raw_zonesummary!$A6)="Existing",Raw_zonesummary!B6,"") -> EL1 EAST PERIM PLNM (G.E7) | B7: =IF(TRIM(Raw_zonesummary!$A6)="Existing",Raw_zonesummary!C6,"") -> EL1 EAST PERIM PLNM (G.E7) | C7: =IF(TRIM(Raw_zonesummary!$A6)="Existing",Raw_zonesummary!D6,"") -> No | D7: =IF(TRIM(Raw_zonesummary!$A6)="Existing",Raw_zonesummary!P6,"") -> Plenum | E7: =IF(TRIM(Raw_zonesummary!$A6)="Existing",Raw_zonesummary!Q6,"") -> - | F7: =IF(TRIM(Raw_zonesummary!$A6)="Existing",Raw_zonesummary!R6,"") -> Plenum | G7: =IFERROR(H7*J7/H33,"") -> 0 | H7: =IF(TRIM(Raw_zonesummary!$A6)="Existing",Raw_zonesummary!E6,"") -> 0 | I7: =IF(TRIM(Raw_zonesummary!$A6)="Existing",Raw_zonesummary!I6,"") -> 16097.08 | J7: =IF(TRIM(Raw_zonesummary!$A6)="Existing",Raw_zonesummary!J6,"") -> 1 | K7: =IF(TRIM(Raw_zonesummary!$A6)="Existing",Raw_zonesummary!K6,"") -> 0
A8: =IF(TRIM(Raw_zonesummary!$A7)="Existing",Raw_zonesummary!B7,"") -> EL1 EAST PERIM PLNM (M.E17) | B8: =IF(TRIM(Raw_zonesummary!$A7)="Existing",Raw_zonesummary!C7,"") -> EL1 EAST PERIM PLNM (M.E17) | C8: =IF(TRIM(Raw_zonesummary!$A7)="Existing",Raw_zonesummary!D7,"") -> No | D8: =IF(TRIM(Raw_zonesummary!$A7)="Existing",Raw_zonesummary!P7,"") -> Plenum | E8: =IF(TRIM(Raw_zonesummary!$A7)="Existing",Raw_zonesummary!Q7,"") -> - | F8: =IF(TRIM(Raw_zonesummary!$A7)="Existing",Raw_zonesummary!R7,"") -> Plenum | G8: =IFERROR(H8*J8/H33,"") -> 0 | H8: =IF(TRIM(Raw_zonesummary!$A7)="Existing",Raw_zonesummary!E7,"") -> 0 | I8: =IF(TRIM(Raw_zonesummary!$A7)="Existing",Raw_zonesummary!I7,"") -> 16097.91 | J8: =IF(TRIM(Raw_zonesummary!$A7)="Existing",Raw_zonesummary!J7,"") -> 1 | K8: =IF(TRIM(Raw_zonesummary!$A7)="Existing",Raw_zonesummary!K7,"") -> 0
A9: =IF(TRIM(Raw_zonesummary!$A8)="Existing",Raw_zonesummary!B8,"") -> EL1 EAST PERIM PLNM (T.E27) | B9: =IF(TRIM(Raw_zonesummary!$A8)="Existing",Raw_zonesummary!C8,"") -> EL1 EAST PERIM PLNM (T.E27) | C9: =IF(TRIM(Raw_zonesummary!$A8)="Existing",Raw_zonesummary!D8,"") -> No | D9: =IF(TRIM(Raw_zonesummary!$A8)="Existing",Raw_zonesummary!P8,"") -> Plenum | E9: =IF(TRIM(Raw_zonesummary!$A8)="Existing",Raw_zonesummary!Q8,"") -> - | F9: =IF(TRIM(Raw_zonesummary!$A8)="Existing",Raw_zonesummary!R8,"") -> Plenum | G9: =IFERROR(H9*J9/H33,"") -> 0 | H9: =IF(TRIM(Raw_zonesummary!$A8)="Existing",Raw_zonesummary!E8,"") -> 0 | I9: =IF(TRIM(Raw_zonesummary!$A8)="Existing",Raw_zonesummary!I8,"") -> 16096.8 | J9: =IF(TRIM(Raw_zonesummary!$A8)="Existing",Raw_zonesummary!J8,"") -> 1 | K9: =IF(TRIM(Raw_zonesummary!$A8)="Existing",Raw_zonesummary!K8,"") -> 0
A10: =IF(TRIM(Raw_zonesummary!$A9)="Existing",Raw_zonesummary!B9,"") -> EL1 NORTH PERIM PLNM (G.N8) | B10: =IF(TRIM(Raw_zonesummary!$A9)="Existing",Raw_zonesummary!C9,"") -> EL1 NORTH PERIM PLNM (G.N8) | C10: =IF(TRIM(Raw_zonesummary!$A9)="Existing",Raw_zonesummary!D9,"") -> No | D10: =IF(TRIM(Raw_zonesummary!$A9)="Existing",Raw_zonesummary!P9,"") -> Plenum | E10: =IF(TRIM(Raw_zonesummary!$A9)="Existing",Raw_zonesummary!Q9,"") -> - | F10: =IF(TRIM(Raw_zonesummary!$A9)="Existing",Raw_zonesummary!R9,"") -> Plenum | G10: =IFERROR(H10*J10/H33,"") -> 0 | H10: =IF(TRIM(Raw_zonesummary!$A9)="Existing",Raw_zonesummary!E9,"") -> 0 | I10: =IF(TRIM(Raw_zonesummary!$A9)="Existing",Raw_zonesummary!I9,"") -> 16097.08 | J10: =IF(TRIM(Raw_zonesummary!$A9)="Existing",Raw_zonesummary!J9,"") -> 1 | K10: =IF(TRIM(Raw_zonesummary!$A9)="Existing",Raw_zonesummary!K9,"") -> 0
A11: =IF(TRIM(Raw_zonesummary!$A10)="Existing",Raw_zonesummary!B10,"") -> EL1 NORTH PERIM PLNM (M.N18) | B11: =IF(TRIM(Raw_zonesummary!$A10)="Existing",Raw_zonesummary!C10,"") -> EL1 NORTH PERIM PLNM (M.N18) | C11: =IF(TRIM(Raw_zonesummary!$A10)="Existing",Raw_zonesummary!D10,"") -> No | D11: =IF(TRIM(Raw_zonesummary!$A10)="Existing",Raw_zonesummary!P10,"") -> Plenum | E11: =IF(TRIM(Raw_zonesummary!$A10)="Existing",Raw_zonesummary!Q10,"") -> - | F11: =IF(TRIM(Raw_zonesummary!$A10)="Existing",Raw_zonesummary!R10,"") -> Plenum | G11: =IFERROR(H11*J11/H33,"") -> 0 | H11: =IF(TRIM(Raw_zonesummary!$A10)="Existing",Raw_zonesummary!E10,"") -> 0 | I11: =IF(TRIM(Raw_zonesummary!$A10)="Existing",Raw_zonesummary!I10,"") -> 16097.91 | J11: =IF(TRIM(Raw_zonesummary!$A10)="Existing",Raw_zonesummary!J10,"") -> 1 | K11: =IF(TRIM(Raw_zonesummary!$A10)="Existing",Raw_zonesummary!K10,"") -> 0
A12: =IF(TRIM(Raw_zonesummary!$A11)="Existing",Raw_zonesummary!B11,"") -> EL1 NORTH PERIM PLNM (T.N28) | B12: =IF(TRIM(Raw_zonesummary!$A11)="Existing",Raw_zonesummary!C11,"") -> EL1 NORTH PERIM PLNM (T.N28) | C12: =IF(TRIM(Raw_zonesummary!$A11)="Existing",Raw_zonesummary!D11,"") -> No | D12: =IF(TRIM(Raw_zonesummary!$A11)="Existing",Raw_zonesummary!P11,"") -> Plenum | E12: =IF(TRIM(Raw_zonesummary!$A11)="Existing",Raw_zonesummary!Q11,"") -> - | F12: =IF(TRIM(Raw_zonesummary!$A11)="Existing",Raw_zonesummary!R11,"") -> Plenum | G12: =IFERROR(H12*J12/H33,"") -> 0 | H12: =IF(TRIM(Raw_zonesummary!$A11)="Existing",Raw_zonesummary!E11,"") -> 0 | I12: =IF(TRIM(Raw_zonesummary!$A11)="Existing",Raw_zonesummary!I11,"") -> 16096.8 | J12: =IF(TRIM(Raw_zonesummary!$A11)="Existing",Raw_zonesummary!J11,"") -> 1 | K12: =IF(TRIM(Raw_zonesummary!$A11)="Existing",Raw_zonesummary!K11,"") -> 0
A13: =IF(TRIM(Raw_zonesummary!$A12)="Existing",Raw_zonesummary!B12,"") -> EL1 SOUTH PERIM PLNM (G.S6) | B13: =IF(TRIM(Raw_zonesummary!$A12)="Existing",Raw_zonesummary!C12,"") -> EL1 SOUTH PERIM PLNM (G.S6) | C13: =IF(TRIM(Raw_zonesummary!$A12)="Existing",Raw_zonesummary!D12,"") -> No | D13: =IF(TRIM(Raw_zonesummary!$A12)="Existing",Raw_zonesummary!P12,"") -> Plenum | E13: =IF(TRIM(Raw_zonesummary!$A12)="Existing",Raw_zonesummary!Q12,"") -> - | F13: =IF(TRIM(Raw_zonesummary!$A12)="Existing",Raw_zonesummary!R12,"") -> Plenum | G13: =IFERROR(H13*J13/H33,"") -> 0 | H13: =IF(TRIM(Raw_zonesummary!$A12)="Existing",Raw_zonesummary!E12,"") -> 0 | I13: =IF(TRIM(Raw_zonesummary!$A12)="Existing",Raw_zonesummary!I12,"") -> 16097.08 | J13: =IF(TRIM(Raw_zonesummary!$A12)="Existing",Raw_zonesummary!J12,"") -> 1 | K13: =IF(TRIM(Raw_zonesummary!$A12)="Existing",Raw_zonesummary!K12,"") -> 0
A14: =IF(TRIM(Raw_zonesummary!$A13)="Existing",Raw_zonesummary!B13,"") -> EL1 SOUTH PERIM PLNM (M.S16) | B14: =IF(TRIM(Raw_zonesummary!$A13)="Existing",Raw_zonesummary!C13,"") -> EL1 SOUTH PERIM PLNM (M.S16) | C14: =IF(TRIM(Raw_zonesummary!$A13)="Existing",Raw_zonesummary!D13,"") -> No | D14: =IF(TRIM(Raw_zonesummary!$A13)="Existing",Raw_zonesummary!P13,"") -> Plenum | E14: =IF(TRIM(Raw_zonesummary!$A13)="Existing",Raw_zonesummary!Q13,"") -> - | F14: =IF(TRIM(Raw_zonesummary!$A13)="Existing",Raw_zonesummary!R13,"") -> Plenum | G14: =IFERROR(H14*J14/H33,"") -> 0 | H14: =IF(TRIM(Raw_zonesummary!$A13)="Existing",Raw_zonesummary!E13,"") -> 0 | I14: =IF(TRIM(Raw_zonesummary!$A13)="Existing",Raw_zonesummary!I13,"") -> 16097.91 | J14: =IF(TRIM(Raw_zonesummary!$A13)="Existing",Raw_zonesummary!J13,"") -> 1 | K14: =IF(TRIM(Raw_zonesummary!$A13)="Existing",Raw_zonesummary!K13,"") -> 0
A15: =IF(TRIM(Raw_zonesummary!$A14)="Existing",Raw_zonesummary!B14,"") -> EL1 SOUTH PERIM PLNM (T.S26) | B15: =IF(TRIM(Raw_zonesummary!$A14)="Existing",Raw_zonesummary!C14,"") -> EL1 SOUTH PERIM PLNM (T.S26) | C15: =IF(TRIM(Raw_zonesummary!$A14)="Existing",Raw_zonesummary!D14,"") -> No | D15: =IF(TRIM(Raw_zonesummary!$A14)="Existing",Raw_zonesummary!P14,"") -> Plenum | E15: =IF(TRIM(Raw_zonesummary!$A14)="Existing",Raw_zonesummary!Q14,"") -> - | F15: =IF(TRIM(Raw_zonesummary!$A14)="Existing",Raw_zonesummary!R14,"") -> Plenum | G15: =IFERROR(H15*J15/H33,"") -> 0 | H15: =IF(TRIM(Raw_zonesummary!$A14)="Existing",Raw_zonesummary!E14,"") -> 0 | I15: =IF(TRIM(Raw_zonesummary!$A14)="Existing",Raw_zonesummary!I14,"") -> 16096.8 | J15: =IF(TRIM(Raw_zonesummary!$A14)="Existing",Raw_zonesummary!J14,"") -> 1 | K15: =IF(TRIM(Raw_zonesummary!$A14)="Existing",Raw_zonesummary!K14,"") -> 0
A16: =IF(TRIM(Raw_zonesummary!$A15)="Existing",Raw_zonesummary!B15,"") -> EL1 WEST PERIM PLNM (G.W9) | B16: =IF(TRIM(Raw_zonesummary!$A15)="Existing",Raw_zonesummary!C15,"") -> EL1 WEST PERIM PLNM (G.W9) | C16: =IF(TRIM(Raw_zonesummary!$A15)="Existing",Raw_zonesummary!D15,"") -> No | D16: =IF(TRIM(Raw_zonesummary!$A15)="Existing",Raw_zonesummary!P15,"") -> Plenum | E16: =IF(TRIM(Raw_zonesummary!$A15)="Existing",Raw_zonesummary!Q15,"") -> - | F16: =IF(TRIM(Raw_zonesummary!$A15)="Existing",Raw_zonesummary!R15,"") -> Plenum | G16: =IFERROR(H16*J16/H33,"") -> 0 | H16: =IF(TRIM(Raw_zonesummary!$A15)="Existing",Raw_zonesummary!E15,"") -> 0 | I16: =IF(TRIM(Raw_zonesummary!$A15)="Existing",Raw_zonesummary!I15,"") -> 16097.08 | J16: =IF(TRIM(Raw_zonesummary!$A15)="Existing",Raw_zonesummary!J15,"") -> 1 | K16: =IF(TRIM(Raw_zonesummary!$A15)="Existing",Raw_zonesummary!K15,"") -> 0
A17: =IF(TRIM(Raw_zonesummary!$A16)="Existing",Raw_zonesummary!B16,"") -> EL1 WEST PERIM PLNM (M.W19) | B17: =IF(TRIM(Raw_zonesummary!$A16)="Existing",Raw_zonesummary!C16,"") -> EL1 WEST PERIM PLNM (M.W19) | C17: =IF(TRIM(Raw_zonesummary!$A16)="Existing",Raw_zonesummary!D16,"") -> No | D17: =IF(TRIM(Raw_zonesummary!$A16)="Existing",Raw_zonesummary!P16,"") -> Plenum | E17: =IF(TRIM(Raw_zonesummary!$A16)="Existing",Raw_zonesummary!Q16,"") -> - | F17: =IF(TRIM(Raw_zonesummary!$A16)="Existing",Raw_zonesummary!R16,"") -> Plenum | G17: =IFERROR(H17*J17/H33,"") -> 0 | H17: =IF(TRIM(Raw_zonesummary!$A16)="Existing",Raw_zonesummary!E16,"") -> 0 | I17: =IF(TRIM(Raw_zonesummary!$A16)="Existing",Raw_zonesummary!I16,"") -> 16097.91 | J17: =IF(TRIM(Raw_zonesummary!$A16)="Existing",Raw_zonesummary!J16,"") -> 1 | K17: =IF(TRIM(Raw_zonesummary!$A16)="Existing",Raw_zonesummary!K16,"") -> 0
A18: =IF(TRIM(Raw_zonesummary!$A17)="Existing",Raw_zonesummary!B17,"") -> EL1 WEST PERIM PLNM (T.W29) | B18: =IF(TRIM(Raw_zonesummary!$A17)="Existing",Raw_zonesummary!C17,"") -> EL1 WEST PERIM PLNM (T.W29) | C18: =IF(TRIM(Raw_zonesummary!$A17)="Existing",Raw_zonesummary!D17,"") -> No | D18: =IF(TRIM(Raw_zonesummary!$A17)="Existing",Raw_zonesummary!P17,"") -> Plenum | E18: =IF(TRIM(Raw_zonesummary!$A17)="Existing",Raw_zonesummary!Q17,"") -> - | F18: =IF(TRIM(Raw_zonesummary!$A17)="Existing",Raw_zonesummary!R17,"") -> Plenum | G18: =IFERROR(H18*J18/H33,"") -> 0 | H18: =IF(TRIM(Raw_zonesummary!$A17)="Existing",Raw_zonesummary!E17,"") -> 0 | I18: =IF(TRIM(Raw_zonesummary!$A17)="Existing",Raw_zonesummary!I17,"") -> 16096.8 | J18: =IF(TRIM(Raw_zonesummary!$A17)="Existing",Raw_zonesummary!J17,"") -> 1 | K18: =IF(TRIM(Raw_zonesummary!$A17)="Existing",Raw_zonesummary!K17,"") -> 0
A19: =IF(TRIM(Raw_zonesummary!$A18)="Existing",Raw_zonesummary!B18,"") -> RETAILSALES EL1 CORE SPC (M.C15) | B19: =IF(TRIM(Raw_zonesummary!$A18)="Existing",Raw_zonesummary!C18,"") -> RETAILSALES EL1 CORE SPC (M.C15) | C19: =IF(TRIM(Raw_zonesummary!$A18)="Existing",Raw_zonesummary!D18,"") -> Yes | D19: =IF(TRIM(Raw_zonesummary!$A18)="Existing",Raw_zonesummary!P18,"") -> Retail_sales | E19: =IF(TRIM(Raw_zonesummary!$A18)="Existing",Raw_zonesummary!Q18,"") -> Main | F19: =IF(TRIM(Raw_zonesummary!$A18)="Existing",Raw_zonesummary!R18,"") -> Retail | G19: =IFERROR(H19*J19/H33,"") -> 0.24083335 | H19: =IF(TRIM(Raw_zonesummary!$A18)="Existing",Raw_zonesummary!E18,"") -> 28902.82 | I19: =IF(TRIM(Raw_zonesummary!$A18)="Existing",Raw_zonesummary!I18,"") -> 433563.47 | J19: =IF(TRIM(Raw_zonesummary!$A18)="Existing",Raw_zonesummary!J18,"") -> 1 | K19: =IF(TRIM(Raw_zonesummary!$A18)="Existing",Raw_zonesummary!K18,"") -> 8.33
A20: =IF(TRIM(Raw_zonesummary!$A19)="Existing",Raw_zonesummary!B19,"") -> RETAILSALES EL1 CORE SPC (T.C25) | B20: =IF(TRIM(Raw_zonesummary!$A19)="Existing",Raw_zonesummary!C19,"") -> RETAILSALES EL1 CORE SPC (T.C25) | C20: =IF(TRIM(Raw_zonesummary!$A19)="Existing",Raw_zonesummary!D19,"") -> Yes | D20: =IF(TRIM(Raw_zonesummary!$A19)="Existing",Raw_zonesummary!P19,"") -> Retail_sales | E20: =IF(TRIM(Raw_zonesummary!$A19)="Existing",Raw_zonesummary!Q19,"") -> Main | F20: =IF(TRIM(Raw_zonesummary!$A19)="Existing",Raw_zonesummary!R19,"") -> Retail | G20: =IFERROR(H20*J20/H33,"") -> 0.24083335 | H20: =IF(TRIM(Raw_zonesummary!$A19)="Existing",Raw_zonesummary!E19,"") -> 28902.82 | I20: =IF(TRIM(Raw_zonesummary!$A19)="Existing",Raw_zonesummary!I19,"") -> 433563.47 | J20: =IF(TRIM(Raw_zonesummary!$A19)="Existing",Raw_zonesummary!J19,"") -> 1 | K20: =IF(TRIM(Raw_zonesummary!$A19)="Existing",Raw_zonesummary!K19,"") -> 8.33
A21: =IF(TRIM(Raw_zonesummary!$A20)="Existing",Raw_zonesummary!B20,"") -> RETAILSALES EL1 EAST PERIM SPC (G.E2) | B21: =IF(TRIM(Raw_zonesummary!$A20)="Existing",Raw_zonesummary!C20,"") -> RETAILSALES EL1 EAST PERIM SPC (G.E2) | C21: =IF(TRIM(Raw_zonesummary!$A20)="Existing",Raw_zonesummary!D20,"") -> Yes | D21: =IF(TRIM(Raw_zonesummary!$A20)="Existing",Raw_zonesummary!P20,"") -> Retail_sales | E21: =IF(TRIM(Raw_zonesummary!$A20)="Existing",Raw_zonesummary!Q20,"") -> Alternative | F21: =IF(TRIM(Raw_zonesummary!$A20)="Existing",Raw_zonesummary!R20,"") -> Retail | G21: =IFERROR(H21*J21/H33,"") -> 0.023124995 | H21: =IF(TRIM(Raw_zonesummary!$A20)="Existing",Raw_zonesummary!E20,"") -> 2775.27 | I21: =IF(TRIM(Raw_zonesummary!$A20)="Existing",Raw_zonesummary!I20,"") -> 41631.09 | J21: =IF(TRIM(Raw_zonesummary!$A20)="Existing",Raw_zonesummary!J20,"") -> 1 | K21: =IF(TRIM(Raw_zonesummary!$A20)="Existing",Raw_zonesummary!K20,"") -> 8.33
A22: =IF(TRIM(Raw_zonesummary!$A21)="Existing",Raw_zonesummary!B21,"") -> RETAILSALES EL1 EAST PERIM SPC (M.E12) | B22: =IF(TRIM(Raw_zonesummary!$A21)="Existing",Raw_zonesummary!C21,"") -> RETAILSALES EL1 EAST PERIM SPC (M.E12) | C22: =IF(TRIM(Raw_zonesummary!$A21)="Existing",Raw_zonesummary!D21,"") -> Yes | D22: =IF(TRIM(Raw_zonesummary!$A21)="Existing",Raw_zonesummary!P21,"") -> Retail_sales | E22: =IF(TRIM(Raw_zonesummary!$A21)="Existing",Raw_zonesummary!Q21,"") -> Main | F22: =IF(TRIM(Raw_zonesummary!$A21)="Existing",Raw_zonesummary!R21,"") -> Retail | G22: =IFERROR(H22*J22/H33,"") -> 0.023124995 | H22: =IF(TRIM(Raw_zonesummary!$A21)="Existing",Raw_zonesummary!E21,"") -> 2775.27 | I22: =IF(TRIM(Raw_zonesummary!$A21)="Existing",Raw_zonesummary!I21,"") -> 41631.09 | J22: =IF(TRIM(Raw_zonesummary!$A21)="Existing",Raw_zonesummary!J21,"") -> 1 | K22: =IF(TRIM(Raw_zonesummary!$A21)="Existing",Raw_zonesummary!K21,"") -> 8.33
A23: =IF(TRIM(Raw_zonesummary!$A22)="Existing",Raw_zonesummary!B22,"") -> RETAILSALES EL1 EAST PERIM SPC (T.E22) | B23: =IF(TRIM(Raw_zonesummary!$A22)="Existing",Raw_zonesummary!C22,"") -> RETAILSALES EL1 EAST PERIM SPC (T.E22) | C23: =IF(TRIM(Raw_zonesummary!$A22)="Existing",Raw_zonesummary!D22,"") -> Yes | D23: =IF(TRIM(Raw_zonesummary!$A22)="Existing",Raw_zonesummary!P22,"") -> Retail_sales | E23: =IF(TRIM(Raw_zonesummary!$A22)="Existing",Raw_zonesummary!Q22,"") -> Main | F23: =IF(TRIM(Raw_zonesummary!$A22)="Existing",Raw_zonesummary!R22,"") -> Retail | G23: =IFERROR(H23*J23/H33,"") -> 0.023124995 | H23: =IF(TRIM(Raw_zonesummary!$A22)="Existing",Raw_zonesummary!E22,"") -> 2775.27 | I23: =IF(TRIM(Raw_zonesummary!$A22)="Existing",Raw_zonesummary!I22,"") -> 41631.09 | J23: =IF(TRIM(Raw_zonesummary!$A22)="Existing",Raw_zonesummary!J22,"") -> 1 | K23: =IF(TRIM(Raw_zonesummary!$A22)="Existing",Raw_zonesummary!K22,"") -> 8.33
A24: =IF(TRIM(Raw_zonesummary!$A23)="Existing",Raw_zonesummary!B23,"") -> RETAILSALES EL1 NORTH PERIM SPC (G.N3) | B24: =IF(TRIM(Raw_zonesummary!$A23)="Existing",Raw_zonesummary!C23,"") -> RETAILSALES EL1 NORTH PERIM SPC (G.N3) | C24: =IF(TRIM(Raw_zonesummary!$A23)="Existing",Raw_zonesummary!D23,"") -> Yes | D24: =IF(TRIM(Raw_zonesummary!$A23)="Existing",Raw_zonesummary!P23,"") -> Retail_sales | E24: =IF(TRIM(Raw_zonesummary!$A23)="Existing",Raw_zonesummary!Q23,"") -> Main | F24: =IF(TRIM(Raw_zonesummary!$A23)="Existing",Raw_zonesummary!R23,"") -> Retail | G24: =IFERROR(H24*J24/H33,"") -> 0.023124995 | H24: =IF(TRIM(Raw_zonesummary!$A23)="Existing",Raw_zonesummary!E23,"") -> 2775.27 | I24: =IF(TRIM(Raw_zonesummary!$A23)="Existing",Raw_zonesummary!I23,"") -> 41631.09 | J24: =IF(TRIM(Raw_zonesummary!$A23)="Existing",Raw_zonesummary!J23,"") -> 1 | K24: =IF(TRIM(Raw_zonesummary!$A23)="Existing",Raw_zonesummary!K23,"") -> 8.33
A25: =IF(TRIM(Raw_zonesummary!$A24)="Existing",Raw_zonesummary!B24,"") -> RETAILSALES EL1 NORTH PERIM SPC (M.N13) | B25: =IF(TRIM(Raw_zonesummary!$A24)="Existing",Raw_zonesummary!C24,"") -> RETAILSALES EL1 NORTH PERIM SPC (M.N13) | C25: =IF(TRIM(Raw_zonesummary!$A24)="Existing",Raw_zonesummary!D24,"") -> Yes | D25: =IF(TRIM(Raw_zonesummary!$A24)="Existing",Raw_zonesummary!P24,"") -> Retail_sales | E25: =IF(TRIM(Raw_zonesummary!$A24)="Existing",Raw_zonesummary!Q24,"") -> Main | F25: =IF(TRIM(Raw_zonesummary!$A24)="Existing",Raw_zonesummary!R24,"") -> Retail | G25: =IFERROR(H25*J25/H33,"") -> 0.023124995 | H25: =IF(TRIM(Raw_zonesummary!$A24)="Existing",Raw_zonesummary!E24,"") -> 2775.27 | I25: =IF(TRIM(Raw_zonesummary!$A24)="Existing",Raw_zonesummary!I24,"") -> 41631.09 | J25: =IF(TRIM(Raw_zonesummary!$A24)="Existing",Raw_zonesummary!J24,"") -> 1 | K25: =IF(TRIM(Raw_zonesummary!$A24)="Existing",Raw_zonesummary!K24,"") -> 8.33
A26: =IF(TRIM(Raw_zonesummary!$A25)="Existing",Raw_zonesummary!B25,"") -> RETAILSALES EL1 NORTH PERIM SPC (T.N23) | B26: =IF(TRIM(Raw_zonesummary!$A25)="Existing",Raw_zonesummary!C25,"") -> RETAILSALES EL1 NORTH PERIM SPC (T.N23) | C26: =IF(TRIM(Raw_zonesummary!$A25)="Existing",Raw_zonesummary!D25,"") -> Yes | D26: =IF(TRIM(Raw_zonesummary!$A25)="Existing",Raw_zonesummary!P25,"") -> Retail_sales | E26: =IF(TRIM(Raw_zonesummary!$A25)="Existing",Raw_zonesummary!Q25,"") -> Main | F26: =IF(TRIM(Raw_zonesummary!$A25)="Existing",Raw_zonesummary!R25,"") -> Retail | G26: =IFERROR(H26*J26/H33,"") -> 0.023124995 | H26: =IF(TRIM(Raw_zonesummary!$A25)="Existing",Raw_zonesummary!E25,"") -> 2775.27 | I26: =IF(TRIM(Raw_zonesummary!$A25)="Existing",Raw_zonesummary!I25,"") -> 41631.09 | J26: =IF(TRIM(Raw_zonesummary!$A25)="Existing",Raw_zonesummary!J25,"") -> 1 | K26: =IF(TRIM(Raw_zonesummary!$A25)="Existing",Raw_zonesummary!K25,"") -> 8.33
A27: =IF(TRIM(Raw_zonesummary!$A26)="Existing",Raw_zonesummary!B26,"") -> RETAILSALES EL1 SOUTH PERIM SPC (G.S1) | B27: =IF(TRIM(Raw_zonesummary!$A26)="Existing",Raw_zonesummary!C26,"") -> RETAILSALES EL1 SOUTH PERIM SPC (G.S1) | C27: =IF(TRIM(Raw_zonesummary!$A26)="Existing",Raw_zonesummary!D26,"") -> Yes | D27: =IF(TRIM(Raw_zonesummary!$A26)="Existing",Raw_zonesummary!P26,"") -> Retail_sales | E27: =IF(TRIM(Raw_zonesummary!$A26)="Existing",Raw_zonesummary!Q26,"") -> Main | F27: =IF(TRIM(Raw_zonesummary!$A26)="Existing",Raw_zonesummary!R26,"") -> Retail | G27: =IFERROR(H27*J27/H33,"") -> 0.023124995 | H27: =IF(TRIM(Raw_zonesummary!$A26)="Existing",Raw_zonesummary!E26,"") -> 2775.27 | I27: =IF(TRIM(Raw_zonesummary!$A26)="Existing",Raw_zonesummary!I26,"") -> 41631.09 | J27: =IF(TRIM(Raw_zonesummary!$A26)="Existing",Raw_zonesummary!J26,"") -> 1 | K27: =IF(TRIM(Raw_zonesummary!$A26)="Existing",Raw_zonesummary!K26,"") -> 8.33
A28: =IF(TRIM(Raw_zonesummary!$A27)="Existing",Raw_zonesummary!B27,"") -> RETAILSALES EL1 SOUTH PERIM SPC (M.S11) | B28: =IF(TRIM(Raw_zonesummary!$A27)="Existing",Raw_zonesummary!C27,"") -> RETAILSALES EL1 SOUTH PERIM SPC (M.S11) | C28: =IF(TRIM(Raw_zonesummary!$A27)="Existing",Raw_zonesummary!D27,"") -> Yes | D28: =IF(TRIM(Raw_zonesummary!$A27)="Existing",Raw_zonesummary!P27,"") -> Retail_sales | E28: =IF(TRIM(Raw_zonesummary!$A27)="Existing",Raw_zonesummary!Q27,"") -> Main | F28: =IF(TRIM(Raw_zonesummary!$A27)="Existing",Raw_zonesummary!R27,"") -> Retail | G28: =IFERROR(H28*J28/H33,"") -> 0.023124995 | H28: =IF(TRIM(Raw_zonesummary!$A27)="Existing",Raw_zonesummary!E27,"") -> 2775.27 | I28: =IF(TRIM(Raw_zonesummary!$A27)="Existing",Raw_zonesummary!I27,"") -> 41631.09 | J28: =IF(TRIM(Raw_zonesummary!$A27)="Existing",Raw_zonesummary!J27,"") -> 1 | K28: =IF(TRIM(Raw_zonesummary!$A27)="Existing",Raw_zonesummary!K27,"") -> 8.33
A29: =IF(TRIM(Raw_zonesummary!$A28)="Existing",Raw_zonesummary!B28,"") -> RETAILSALES EL1 SOUTH PERIM SPC (T.S21) | B29: =IF(TRIM(Raw_zonesummary!$A28)="Existing",Raw_zonesummary!C28,"") -> RETAILSALES EL1 SOUTH PERIM SPC (T.S21) | C29: =IF(TRIM(Raw_zonesummary!$A28)="Existing",Raw_zonesummary!D28,"") -> Yes | D29: =IF(TRIM(Raw_zonesummary!$A28)="Existing",Raw_zonesummary!P28,"") -> Retail_sales | E29: =IF(TRIM(Raw_zonesummary!$A28)="Existing",Raw_zonesummary!Q28,"") -> Main | F29: =IF(TRIM(Raw_zonesummary!$A28)="Existing",Raw_zonesummary!R28,"") -> Retail | G29: =IFERROR(H29*J29/H33,"") -> 0.023124995 | H29: =IF(TRIM(Raw_zonesummary!$A28)="Existing",Raw_zonesummary!E28,"") -> 2775.27 | I29: =IF(TRIM(Raw_zonesummary!$A28)="Existing",Raw_zonesummary!I28,"") -> 41631.09 | J29: =IF(TRIM(Raw_zonesummary!$A28)="Existing",Raw_zonesummary!J28,"") -> 1 | K29: =IF(TRIM(Raw_zonesummary!$A28)="Existing",Raw_zonesummary!K28,"") -> 8.33
A30: =IF(TRIM(Raw_zonesummary!$A29)="Existing",Raw_zonesummary!B29,"") -> RETAILSALES EL1 WEST PERIM SPC (G.W4) | B30: =IF(TRIM(Raw_zonesummary!$A29)="Existing",Raw_zonesummary!C29,"") -> RETAILSALES EL1 WEST PERIM SPC (G.W4) | C30: =IF(TRIM(Raw_zonesummary!$A29)="Existing",Raw_zonesummary!D29,"") -> Yes | D30: =IF(TRIM(Raw_zonesummary!$A29)="Existing",Raw_zonesummary!P29,"") -> Retail_sales | E30: =IF(TRIM(Raw_zonesummary!$A29)="Existing",Raw_zonesummary!Q29,"") -> Main | F30: =IF(TRIM(Raw_zonesummary!$A29)="Existing",Raw_zonesummary!R29,"") -> Retail | G30: =IFERROR(H30*J30/H33,"") -> 0.023124995 | H30: =IF(TRIM(Raw_zonesummary!$A29)="Existing",Raw_zonesummary!E29,"") -> 2775.27 | I30: =IF(TRIM(Raw_zonesummary!$A29)="Existing",Raw_zonesummary!I29,"") -> 41631.09 | J30: =IF(TRIM(Raw_zonesummary!$A29)="Existing",Raw_zonesummary!J29,"") -> 1 | K30: =IF(TRIM(Raw_zonesummary!$A29)="Existing",Raw_zonesummary!K29,"") -> 8.33
A31: =IF(TRIM(Raw_zonesummary!$A30)="Existing",Raw_zonesummary!B30,"") -> RETAILSALES EL1 WEST PERIM SPC (M.W14) | B31: =IF(TRIM(Raw_zonesummary!$A30)="Existing",Raw_zonesummary!C30,"") -> RETAILSALES EL1 WEST PERIM SPC (M.W14) | C31: =IF(TRIM(Raw_zonesummary!$A30)="Existing",Raw_zonesummary!D30,"") -> Yes | D31: =IF(TRIM(Raw_zonesummary!$A30)="Existing",Raw_zonesummary!P30,"") -> Retail_sales | E31: =IF(TRIM(Raw_zonesummary!$A30)="Existing",Raw_zonesummary!Q30,"") -> Main | F31: =IF(TRIM(Raw_zonesummary!$A30)="Existing",Raw_zonesummary!R30,"") -> Retail | G31: =IFERROR(H31*J31/H33,"") -> 0.023124995 | H31: =IF(TRIM(Raw_zonesummary!$A30)="Existing",Raw_zonesummary!E30,"") -> 2775.27 | I31: =IF(TRIM(Raw_zonesummary!$A30)="Existing",Raw_zonesummary!I30,"") -> 41631.09 | J31: =IF(TRIM(Raw_zonesummary!$A30)="Existing",Raw_zonesummary!J30,"") -> 1 | K31: =IF(TRIM(Raw_zonesummary!$A30)="Existing",Raw_zonesummary!K30,"") -> 8.33
A32: =IF(TRIM(Raw_zonesummary!$A31)="Existing",Raw_zonesummary!B31,"") -> RETAILSALES EL1 WEST PERIM SPC (T.W24) | B32: =IF(TRIM(Raw_zonesummary!$A31)="Existing",Raw_zonesummary!C31,"") -> RETAILSALES EL1 WEST PERIM SPC (T.W24) | C32: =IF(TRIM(Raw_zonesummary!$A31)="Existing",Raw_zonesummary!D31,"") -> Yes | D32: =IF(TRIM(Raw_zonesummary!$A31)="Existing",Raw_zonesummary!P31,"") -> Retail_sales | E32: =IF(TRIM(Raw_zonesummary!$A31)="Existing",Raw_zonesummary!Q31,"") -> Main | F32: =IF(TRIM(Raw_zonesummary!$A31)="Existing",Raw_zonesummary!R31,"") -> Retail | G32: =IFERROR(H32*J32/H33,"") -> 0.023124995 | H32: =IF(TRIM(Raw_zonesummary!$A31)="Existing",Raw_zonesummary!E31,"") -> 2775.27 | I32: =IF(TRIM(Raw_zonesummary!$A31)="Existing",Raw_zonesummary!I31,"") -> 41631.09 | J32: =IF(TRIM(Raw_zonesummary!$A31)="Existing",Raw_zonesummary!J31,"") -> 1 | K32: =IF(TRIM(Raw_zonesummary!$A31)="Existing",Raw_zonesummary!K31,"") -> 8.33
A33: ="Total (" & COUNTIF(A$3:INDEX(A:A,ROW()-1),"?*") & " Space)" -> Total (30 Space) | B33: ="Total (" & COUNTIF(A$3:INDEX(A:A,ROW()-1),"?*") & " Space)" -> Total (30 Space) | C33: ="Total (" & COUNTIF(C$2:INDEX(C:C,ROW()-1),"Yes") & " Conditioned zones, " & COUNTIF(C$2:INDEX(C:C,ROW()-1),"No") & " Unconditioned Zones)" -> Total (15 Conditioned zones, 15 Unconditioned Zones) | H33: =SUMPRODUCT($H$3:INDEX(H:H,ROW()-1), $J$3:INDEX(J:J,ROW()-1)) -> 120011.7

Sheet Envelope
A1: ="Envelope - "&Prototype!A2 -> Envelope - Retail - Multistory Large
A2: Element | B2: Prototype | C2: Assembly Type | D2: Construction | E2: Unit | F2: Vintage | G2: Selected T24 | H2: Note | I2: CZ01 | J2: CZ02 | K2: CZ03 | L2: CZ04 | M2: CZ05 | N2: CZ06 | O2: CZ07 | P2: CZ08 | Q2: CZ09 | R2: CZ10 | S2: CZ11 | T2: CZ12 | U2: CZ13 | V2: CZ14 | W2: CZ15 | X2: CZ16
A3: External Wall | B3: =Prototype!$A$2 -> Retail - Multistory Large | C3: - | D3: {=_xlfn.LET( _xlpm.v, $F3, _xlpm.el, $A3, _xlpm.rV, Raw_envelope!$B$2:$B$2000, _xlpm.col, _xlfn.SWITCH(_xlpm.el, "External Wall", Raw_envelope!$E$2:$E$2000, "Roof", Raw_envelope!$C$2:$C$2000, "Windows", Raw_envelope!$G$2:$G$2000, "" ), _xlpm.r, _xlfn.XMATCH(_xlpm.v, _xlpm.rV, 0), IFERROR(INDEX(_xlpm.col, _xlpm.r), "") )} -> Stucco+Wall Continuous Insulation+Gypsum 5/8in | E3: U-value IP | F3: Existing | G3: Weighted average | I3: {=_xlfn.LET( _xlpm.cz, I$2, _xlpm.v, $F3, _xlpm.el, $A3, _xlpm.unit, $E3, _xlpm.rCZ, Raw_envelope!$A:$A, _xlpm.rV, Raw_envelope!$B:$B, _xlpm.col, _xlfn.SWITCH(TRUE, AND(_xlpm.el="External Wall", _xlpm.unit="U-value IP"), Raw_envelope!$F:$F, AND(_xlpm.el="Roof", _xlpm.unit="U-value IP"), Raw_envelope!$D:$D, AND(_xlpm.el="Windows", _xlpm.unit="U-value IP"), Raw_envelope!$H:$H, AND(_xlpm.el="Windows", _xlpm.unit="SHGC"), Raw_envelope!$I:$I, AND(_xlpm.el="Windows", _xlpm.unit="Visible Transmittance"), Raw_envelope!$J:$J, "" ), _xlpm.r, _xlfn.XMATCH(1,(_xlpm.rCZ=_xlpm.cz)*(_xlpm.rV=_xlpm.v),0), IFERROR(INDEX(_xlpm.col,_xlpm.r),"") )} -> 0.393 | J3: {=_xlfn.LET( _xlpm.cz, J$2, _xlpm.v, $F3, _xlpm.el, $A3, _xlpm.unit, $E3, _xlpm.rCZ, Raw_envelope!$A:$A, _xlpm.rV, Raw_envelope!$B:$B, _xlpm.col, _xlfn.SWITCH(TRUE, AND(_xlpm.el="External Wall", _xlpm.unit="U-value IP"), Raw_envelope!$F:$F, AND(_xlpm.el="Roof", _xlpm.unit="U-value IP"), Raw_envelope!$D:$D, AND(_xlpm.el="Windows", _xlpm.unit="U-value IP"), Raw_envelope!$H:$H, AND(_xlpm.el="Windows", _xlpm.unit="SHGC"), Raw_envelope!$I:$I, AND(_xlpm.el="Windows", _xlpm.unit="Visible Transmittance"), Raw_envelope!$J:$J, "" ), _xlpm.r, _xlfn.XMATCH(1,(_xlpm.rCZ=_xlpm.cz)*(_xlpm.rV=_xlpm.v),0), IFERROR(INDEX(_xlpm.col,_xlpm.r),"") )} -> 0.609 | K3: {=_xlfn.LET( _xlpm.cz, K$2, _xlpm.v, $F3, _xlpm.el, $A3, _xlpm.unit, $E3, _xlpm.rCZ, Raw_envelope!$A:$A, _xlpm.rV, Raw_envelope!$B:$B, _xlpm.col, _xlfn.SWITCH(TRUE, AND(_xlpm.el="External Wall", _xlpm.unit="U-value IP"), Raw_envelope!$F:$F, AND(_xlpm.el="Roof", _xlpm.unit="U-value IP"), Raw_envelope!$D:$D, AND(_xlpm.el="Windows", _xlpm.unit="U-value IP"), Raw_envelope!$H:$H, AND(_xlpm.el="Windows", _xlpm.unit="SHGC"), Raw_envelope!$I:$I, AND(_xlpm.el="Windows", _xlpm.unit="Visible Transmittance"), Raw_envelope!$J:$J, "" ), _xlpm.r, _xlfn.XMATCH(1,(_xlpm.rCZ=_xlpm.cz)*(_xlpm.rV=_xlpm.v),0), IFERROR(INDEX(_xlpm.col,_xlpm.r),"") )} -> 0.577 | L3: {=_xlfn.LET( _xlpm.cz, L$2, _xlpm.v, $F3, _xlpm.el, $A3, _xlpm.unit, $E3, _xlpm.rCZ, Raw_envelope!$A:$A, _xlpm.rV, Raw_envelope!$B:$B, _xlpm.col, _xlfn.SWITCH(TRUE, AND(_xlpm.el="External Wall", _xlpm.unit="U-value IP"), Raw_envelope!$F:$F, AND(_xlpm.el="Roof", _xlpm.unit="U-value IP"), Raw_envelope!$D:$D, AND(_xlpm.el="Windows", _xlpm.unit="U-value IP"), Raw_envelope!$H:$H, AND(_xlpm.el="Windows", _xlpm.unit="SHGC"), Raw_envelope!$I:$I, AND(_xlpm.el="Windows", _xlpm.unit="Visible Transmittance"), Raw_envelope!$J:$J, "" ), _xlpm.r, _xlfn.XMATCH(1,(_xlpm.rCZ=_xlpm.cz)*(_xlpm.rV=_xlpm.v),0), IFERROR(INDEX(_xlpm.col,_xlpm.r),"") )} -> 0.629 | M3: {=_xlfn.LET( _xlpm.cz, M$2, _xlpm.v, $F3, _xlpm.el, $A3, _xlpm.unit, $E3, _xlpm.rCZ, Raw_envelope!$A:$A, _xlpm.rV, Raw_envelope!$B:$B, _xlpm.col, _xlfn.SWITCH(TRUE, AND(_xlpm.el="External Wall", _xlpm.unit="U-value IP"), Raw_envelope!$F:$F, AND(_xlpm.el="Roof", _xlpm.unit="U-value IP"), Raw_envelope!$D:$D, AND(_xlpm.el="Windows", _xlpm.unit="U-value IP"), Raw_envelope!$H:$H, AND(_xlpm.el="Windows", _xlpm.unit="SHGC"), Raw_envelope!$I:$I, AND(_xlpm.el="Windows", _xlpm.unit="Visible Transmittance"), Raw_envelope!$J:$J, "" ), _xlpm.r, _xlfn.XMATCH(1,(_xlpm.rCZ=_xlpm.cz)*(_xlpm.rV=_xlpm.v),0), IFERROR(INDEX(_xlpm.col,_xlpm.r),"") )} -> 0.615 | N3: {=_xlfn.LET( _xlpm.cz, N$2, _xlpm.v, $F3, _xlpm.el, $A3, _xlpm.unit, $E3, _xlpm.rCZ, Raw_envelope!$A:$A, _xlpm.rV, Raw_envelope!$B:$B, _xlpm.col, _xlfn.SWITCH(TRUE, AND(_xlpm.el="External Wall", _xlpm.unit="U-value IP"), Raw_envelope!$F:$F, AND(_xlpm.el="Roof", _xlpm.unit="U-value IP"), Raw_envelope!$D:$D, AND(_xlpm.el="Windows", _xlpm.unit="U-value IP"), Raw_envelope!$H:$H, AND(_xlpm.el="Windows", _xlpm.unit="SHGC"), Raw_envelope!$I:$I, AND(_xlpm.el="Windows", _xlpm.unit="Visible Transmittance"), Raw_envelope!$J:$J, "" ), _xlpm.r, _xlfn.XMATCH(1,(_xlpm.rCZ=_xlpm.cz)*(_xlpm.rV=_xlpm.v),0), IFERROR(INDEX(_xlpm.col,_xlpm.r),"") )} -> 0.623 | O3: {=_xlfn.LET( _xlpm.cz, O$2, _xlpm.v, $F3, _xlpm.el, $A3, _xlpm.unit, $E3, _xlpm.rCZ, Raw_envelope!$A:$A, _xlpm.rV, Raw_envelope!$B:$B, _xlpm.col, _xlfn.SWITCH(TRUE, AND(_xlpm.el="External Wall", _xlpm.unit="U-value IP"), Raw_envelope!$F:$F, AND(_xlpm.el="Roof", _xlpm.unit="U-value IP"), Raw_envelope!$D:$D, AND(_xlpm.el="Windows", _xlpm.unit="U-value IP"), Raw_envelope!$H:$H, AND(_xlpm.el="Windows", _xlpm.unit="SHGC"), Raw_envelope!$I:$I, AND(_xlpm.el="Windows", _xlpm.unit="Visible Transmittance"), Raw_envelope!$J:$J, "" ), _xlpm.r, _xlfn.XMATCH(1,(_xlpm.rCZ=_xlpm.cz)*(_xlpm.rV=_xlpm.v),0), IFERROR(INDEX(_xlpm.col,_xlpm.r),"") )} -> 0.73 | P3: {=_xlfn.LET( _xlpm.cz, P$2, _xlpm.v, $F3, _xlpm.el, $A3, _xlpm.unit, $E3, _xlpm.rCZ, Raw_envelope!$A:$A, _xlpm.rV, Raw_envelope!$B:$B, _xlpm.col, _xlfn.SWITCH(TRUE, AND(_xlpm.el="External Wall", _xlpm.unit="U-value IP"), Raw_envelope!$F:$F, AND(_xlpm.el="Roof", _xlpm.unit="U-value IP"), Raw_envelope!$D:$D, AND(_xlpm.el="Windows", _xlpm.unit="U-value IP"), Raw_envelope!$H:$H, AND(_xlpm.el="Windows", _xlpm.unit="SHGC"), Raw_envelope!$I:$I, AND(_xlpm.el="Windows", _xlpm.unit="Visible Transmittance"), Raw_envelope!$J:$J, "" ), _xlpm.r, _xlfn.XMATCH(1,(_xlpm.rCZ=_xlpm.cz)*(_xlpm.rV=_xlpm.v),0), IFERROR(INDEX(_xlpm.col,_xlpm.r),"") )} -> 0.626 | ... X3: {=_xlfn.LET( _xlpm.cz, X$2, _xlpm.v, $F3, _xlpm.el, $A3, _xlpm.unit, $E3, _xlpm.rCZ, Raw_envelope!$A:$A, _xlpm.rV, Raw_envelope!$B:$B, _xlpm.col, _xlfn.SWITCH(TRUE, AND(_xlpm.el="External Wall", _xlpm.unit="U-value IP"), Raw_envelope!$F:$F, AND(_xlpm.el="Roof", _xlpm.unit="U-value IP"), Raw_envelope!$D:$D, AND(_xlpm.el="Windows", _xlpm.unit="U-value IP"), Raw_envelope!$H:$H, AND(_xlpm.el="Windows", _xlpm.unit="SHGC"), Raw_envelope!$I:$I, AND(_xlpm.el="Windows", _xlpm.unit="Visible Transmittance"), Raw_envelope!$J:$J, "" ), _xlpm.r, _xlfn.XMATCH(1,(_xlpm.rCZ=_xlpm.cz)*(_xlpm.rV=_xlpm.v),0), IFERROR(INDEX(_xlpm.col,_xlpm.r),"") )} -> 0.357
A4: External Wall | B4: =Prototype!$A$2 -> Retail - Multistory Large | C4: - | D4: {=_xlfn.LET( _xlpm.v, $F4, _xlpm.el, $A4, _xlpm.rV, Raw_envelope!$B$2:$B$2000, _xlpm.col, _xlfn.SWITCH(_xlpm.el, "External Wall", Raw_envelope!$E$2:$E$2000, "Roof", Raw_envelope!$C$2:$C$2000, "Windows", Raw_envelope!$G$2:$G$2000, "" ), _xlpm.r, _xlfn.XMATCH(_xlpm.v, _xlpm.rV, 0), IFERROR(INDEX(_xlpm.col, _xlpm.r), "") )} -> Stucco+Wall Continuous Insulation+Gypsum 5/8in | E4: U-value IP | F4: New Construction | G4: 2025 | I4: {=_xlfn.LET( _xlpm.cz, I$2, _xlpm.v, $F4, _xlpm.el, $A4, _xlpm.unit, $E4, _xlpm.rCZ, Raw_envelope!$A:$A, _xlpm.rV, Raw_envelope!$B:$B, _xlpm.col, _xlfn.SWITCH(TRUE, AND(_xlpm.el="External Wall", _xlpm.unit="U-value IP"), Raw_envelope!$F:$F, AND(_xlpm.el="Roof", _xlpm.unit="U-value IP"), Raw_envelope!$D:$D, AND(_xlpm.el="Windows", _xlpm.unit="U-value IP"), Raw_envelope!$H:$H, AND(_xlpm.el="Windows", _xlpm.unit="SHGC"), Raw_envelope!$I:$I, AND(_xlpm.el="Windows", _xlpm.unit="Visible Transmittance"), Raw_envelope!$J:$J, "" ), _xlpm.r, _xlfn.XMATCH(1,(_xlpm.rCZ=_xlpm.cz)*(_xlpm.rV=_xlpm.v),0), IFERROR(INDEX(_xlpm.col,_xlpm.r),"") )} -> 0.257 | J4: {=_xlfn.LET( _xlpm.cz, J$2, _xlpm.v, $F4, _xlpm.el, $A4, _xlpm.unit, $E4, _xlpm.rCZ, Raw_envelope!$A:$A, _xlpm.rV, Raw_envelope!$B:$B, _xlpm.col, _xlfn.SWITCH(TRUE, AND(_xlpm.el="External Wall", _xlpm.unit="U-value IP"), Raw_envelope!$F:$F, AND(_xlpm.el="Roof", _xlpm.unit="U-value IP"), Raw_envelope!$D:$D, AND(_xlpm.el="Windows", _xlpm.unit="U-value IP"), Raw_envelope!$H:$H, AND(_xlpm.el="Windows", _xlpm.unit="SHGC"), Raw_envelope!$I:$I, AND(_xlpm.el="Windows", _xlpm.unit="Visible Transmittance"), Raw_envelope!$J:$J, "" ), _xlpm.r, _xlfn.XMATCH(1,(_xlpm.rCZ=_xlpm.cz)*(_xlpm.rV=_xlpm.v),0), IFERROR(INDEX(_xlpm.col,_xlpm.r),"") )} -> 1.452 | K4: {=_xlfn.LET( _xlpm.cz, K$2, _xlpm.v, $F4, _xlpm.el, $A4, _xlpm.unit, $E4, _xlpm.rCZ, Raw_envelope!$A:$A, _xlpm.rV, Raw_envelope!$B:$B, _xlpm.col, _xlfn.SWITCH(TRUE, AND(_xlpm.el="External Wall", _xlpm.unit="U-value IP"), Raw_envelope!$F:$F, AND(_xlpm.el="Roof", _xlpm.unit="U-value IP"), Raw_envelope!$D:$D, AND(_xlpm.el="Windows", _xlpm.unit="U-value IP"), Raw_envelope!$H:$H, AND(_xlpm.el="Windows", _xlpm.unit="SHGC"), Raw_envelope!$I:$I, AND(_xlpm.el="Windows", _xlpm.unit="Visible Transmittance"), Raw_envelope!$J:$J, "" ), _xlpm.r, _xlfn.XMATCH(1,(_xlpm.rCZ=_xlpm.cz)*(_xlpm.rV=_xlpm.v),0), IFERROR(INDEX(_xlpm.col,_xlpm.r),"") )} -> 1.452 | L4: {=_xlfn.LET( _xlpm.cz, L$2, _xlpm.v, $F4, _xlpm.el, $A4, _xlpm.unit, $E4, _xlpm.rCZ, Raw_envelope!$A:$A, _xlpm.rV, Raw_envelope!$B:$B, _xlpm.col, _xlfn.SWITCH(TRUE, AND(_xlpm.el="External Wall", _xlpm.unit="U-value IP"), Raw_envelope!$F:$F, AND(_xlpm.el="Roof", _xlpm.unit="U-value IP"), Raw_envelope!$D:$D, AND(_xlpm.el="Windows", _xlpm.unit="U-value IP"), Raw_envelope!$H:$H, AND(_xlpm.el="Windows", _xlpm.unit="SHGC"), Raw_envelope!$I:$I, AND(_xlpm.el="Windows", _xlpm.unit="Visible Transmittance"), Raw_envelope!$J:$J, "" ), _xlpm.r, _xlfn.XMATCH(1,(_xlpm.rCZ=_xlpm.cz)*(_xlpm.rV=_xlpm.v),0), IFERROR(INDEX(_xlpm.col,_xlpm.r),"") )} -> 1.452 | M4: {=_xlfn.LET( _xlpm.cz, M$2, _xlpm.v, $F4, _xlpm.el, $A4, _xlpm.unit, $E4, _xlpm.rCZ, Raw_envelope!$A:$A, _xlpm.rV, Raw_envelope!$B:$B, _xlpm.col, _xlfn.SWITCH(TRUE, AND(_xlpm.el="External Wall", _xlpm.unit="U-value IP"), Raw_envelope!$F:$F, AND(_xlpm.el="Roof", _xlpm.unit="U-value IP"), Raw_envelope!$D:$D, AND(_xlpm.el="Windows", _xlpm.unit="U-value IP"), Raw_envelope!$H:$H, AND(_xlpm.el="Windows", _xlpm.unit="SHGC"), Raw_envelope!$I:$I, AND(_xlpm.el="Windows", _xlpm.unit="Visible Transmittance"), Raw_envelope!$J:$J, "" ), _xlpm.r, _xlfn.XMATCH(1,(_xlpm.rCZ=_xlpm.cz)*(_xlpm.rV=_xlpm.v),0), IFERROR(INDEX(_xlpm.col,_xlpm.r),"") )} -> 1.452 | N4: {=_xlfn.LET( _xlpm.cz, N$2, _xlpm.v, $F4, _xlpm.el, $A4, _xlpm.unit, $E4, _xlpm.rCZ, Raw_envelope!$A:$A, _xlpm.rV, Raw_envelope!$B:$B, _xlpm.col, _xlfn.SWITCH(TRUE, AND(_xlpm.el="External Wall", _xlpm.unit="U-value IP"), Raw_envelope!$F:$F, AND(_xlpm.el="Roof", _xlpm.unit="U-value IP"), Raw_envelope!$D:$D, AND(_xlpm.el="Windows", _xlpm.unit="U-value IP"), Raw_envelope!$H:$H, AND(_xlpm.el="Windows", _xlpm.unit="SHGC"), Raw_envelope!$I:$I, AND(_xlpm.el="Windows", _xlpm.unit="Visible Transmittance"), Raw_envelope!$J:$J, "" ), _xlpm.r, _xlfn.XMATCH(1,(_xlpm.rCZ=_xlpm.cz)*(_xlpm.rV=_xlpm.v),0), IFERROR(INDEX(_xlpm.col,_xlpm.r),"") )} -> 1.515 | O4: {=_xlfn.LET( _xlpm.cz, O$2, _xlpm.v, $F4, _xlpm.el, $A4, _xlpm.unit, $E4, _xlpm.rCZ, Raw_envelope!$A:$A, _xlpm.rV, Raw_envelope!$B:$B, _xlpm.col, _xlfn.SWITCH(TRUE, AND(_xlpm.el="External Wall", _xlpm.unit="U-value IP"), Raw_envelope!$F:$F, AND(_xlpm.el="Roof", _xlpm.unit="U-value IP"), Raw_envelope!$D:$D, AND(_xlpm.el="Windows", _xlpm.unit="U-value IP"), Raw_envelope!$H:$H, AND(_xlpm.el="Windows", _xlpm.unit="SHGC"), Raw_envelope!$I:$I, AND(_xlpm.el="Windows", _xlpm.unit="Visible Transmittance"), Raw_envelope!$J:$J, "" ), _xlpm.r, _xlfn.XMATCH(1,(_xlpm.rCZ=_xlpm.cz)*(_xlpm.rV=_xlpm.v),0), IFERROR(INDEX(_xlpm.col,_xlpm.r),"") )} -> 1.515 | P4: {=_xlfn.LET( _xlpm.cz, P$2, _xlpm.v, $F4, _xlpm.el, $A4, _xlpm.unit, $E4, _xlpm.rCZ, Raw_envelope!$A:$A, _xlpm.rV, Raw_envelope!$B:$B, _xlpm.col, _xlfn.SWITCH(TRUE, AND(_xlpm.el="External Wall", _xlpm.unit="U-value IP"), Raw_envelope!$F:$F, AND(_xlpm.el="Roof", _xlpm.unit="U-value IP"), Raw_envelope!$D:$D, AND(_xlpm.el="Windows", _xlpm.unit="U-value IP"), Raw_envelope!$H:$H, AND(_xlpm.el="Windows", _xlpm.unit="SHGC"), Raw_envelope!$I:$I, AND(_xlpm.el="Windows", _xlpm.unit="Visible Transmittance"), Raw_envelope!$J:$J, "" ), _xlpm.r, _xlfn.XMATCH(1,(_xlpm.rCZ=_xlpm.cz)*(_xlpm.rV=_xlpm.v),0), IFERROR(INDEX(_xlpm.col,_xlpm.r),"") )} -> 1.515 | ... X4: {=_xlfn.LET( _xlpm.cz, X$2, _xlpm.v, $F4, _xlpm.el, $A4, _xlpm.unit, $E4, _xlpm.rCZ, Raw_envelope!$A:$A, _xlpm.rV, Raw_envelope!$B:$B, _xlpm.col, _xlfn.SWITCH(TRUE, AND(_xlpm.el="External Wall", _xlpm.unit="U-value IP"), Raw_envelope!$F:$F, AND(_xlpm.el="Roof", _xlpm.unit="U-value IP"), Raw_envelope!$D:$D, AND(_xlpm.el="Windows", _xlpm.unit="U-value IP"), Raw_envelope!$H:$H, AND(_xlpm.el="Windows", _xlpm.unit="SHGC"), Raw_envelope!$I:$I, AND(_xlpm.el="Windows", _xlpm.unit="Visible Transmittance"), Raw_envelope!$J:$J, "" ), _xlpm.r, _xlfn.XMATCH(1,(_xlpm.rCZ=_xlpm.cz)*(_xlpm.rV=_xlpm.v),0), IFERROR(INDEX(_xlpm.col,_xlpm.r),"") )} -> 0.176
A5: Roof | B5: =Prototype!$A$2 -> Retail - Multistory Large | C5: - | D5: {=_xlfn.LET( _xlpm.v, $F5, _xlpm.el, $A5, _xlpm.rV, Raw_envelope!$B$2:$B$2000, _xlpm.col, _xlfn.SWITCH(_xlpm.el, "External Wall", Raw_envelope!$E$2:$E$2000, "Roof", Raw_envelope!$C$2:$C$2000, "Windows", Raw_envelope!$G$2:$G$2000, "" ), _xlpm.r, _xlfn.XMATCH(_xlpm.v, _xlpm.rV, 0), IFERROR(INDEX(_xlpm.col, _xlpm.r), "") )} -> Roof Membrane+Roof Continuous Insulation+Metal Decking | E5: U-value IP | F5: Existing | G5: Weighted average | I5: {=_xlfn.LET( _xlpm.cz, I$2, _xlpm.v, $F5, _xlpm.el, $A5, _xlpm.unit, $E5, _xlpm.rCZ, Raw_envelope!$A:$A, _xlpm.rV, Raw_envelope!$B:$B, _xlpm.col, _xlfn.SWITCH(TRUE, AND(_xlpm.el="External Wall", _xlpm.unit="U-value IP"), Raw_envelope!$F:$F, AND(_xlpm.el="Roof", _xlpm.unit="U-value IP"), Raw_envelope!$D:$D, AND(_xlpm.el="Windows", _xlpm.unit="U-value IP"), Raw_envelope!$H:$H, AND(_xlpm.el="Windows", _xlpm.unit="SHGC"), Raw_envelope!$I:$I, AND(_xlpm.el="Windows", _xlpm.unit="Visible Transmittance"), Raw_envelope!$J:$J, "" ), _xlpm.r, _xlfn.XMATCH(1,(_xlpm.rCZ=_xlpm.cz)*(_xlpm.rV=_xlpm.v),0), IFERROR(INDEX(_xlpm.col,_xlpm.r),"") )} -> 0.062 | J5: {=_xlfn.LET( _xlpm.cz, J$2, _xlpm.v, $F5, _xlpm.el, $A5, _xlpm.unit, $E5, _xlpm.rCZ, Raw_envelope!$A:$A, _xlpm.rV, Raw_envelope!$B:$B, _xlpm.col, _xlfn.SWITCH(TRUE, AND(_xlpm.el="External Wall", _xlpm.unit="U-value IP"), Raw_envelope!$F:$F, AND(_xlpm.el="Roof", _xlpm.unit="U-value IP"), Raw_envelope!$D:$D, AND(_xlpm.el="Windows", _xlpm.unit="U-value IP"), Raw_envelope!$H:$H, AND(_xlpm.el="Windows", _xlpm.unit="SHGC"), Raw_envelope!$I:$I, AND(_xlpm.el="Windows", _xlpm.unit="Visible Transmittance"), Raw_envelope!$J:$J, "" ), _xlpm.r, _xlfn.XMATCH(1,(_xlpm.rCZ=_xlpm.cz)*(_xlpm.rV=_xlpm.v),0), IFERROR(INDEX(_xlpm.col,_xlpm.r),"") )} -> 0.061 | K5: {=_xlfn.LET( _xlpm.cz, K$2, _xlpm.v, $F5, _xlpm.el, $A5, _xlpm.unit, $E5, _xlpm.rCZ, Raw_envelope!$A:$A, _xlpm.rV, Raw_envelope!$B:$B, _xlpm.col, _xlfn.SWITCH(TRUE, AND(_xlpm.el="External Wall", _xlpm.unit="U-value IP"), Raw_envelope!$F:$F, AND(_xlpm.el="Roof", _xlpm.unit="U-value IP"), Raw_envelope!$D:$D, AND(_xlpm.el="Windows", _xlpm.unit="U-value IP"), Raw_envelope!$H:$H, AND(_xlpm.el="Windows", _xlpm.unit="SHGC"), Raw_envelope!$I:$I, AND(_xlpm.el="Windows", _xlpm.unit="Visible Transmittance"), Raw_envelope!$J:$J, "" ), _xlpm.r, _xlfn.XMATCH(1,(_xlpm.rCZ=_xlpm.cz)*(_xlpm.rV=_xlpm.v),0), IFERROR(INDEX(_xlpm.col,_xlpm.r),"") )} -> 0.062 | L5: {=_xlfn.LET( _xlpm.cz, L$2, _xlpm.v, $F5, _xlpm.el, $A5, _xlpm.unit, $E5, _xlpm.rCZ, Raw_envelope!$A:$A, _xlpm.rV, Raw_envelope!$B:$B, _xlpm.col, _xlfn.SWITCH(TRUE, AND(_xlpm.el="External Wall", _xlpm.unit="U-value IP"), Raw_envelope!$F:$F, AND(_xlpm.el="Roof", _xlpm.unit="U-value IP"), Raw_envelope!$D:$D, AND(_xlpm.el="Windows", _xlpm.unit="U-value IP"), Raw_envelope!$H:$H, AND(_xlpm.el="Windows", _xlpm.unit="SHGC"), Raw_envelope!$I:$I, AND(_xlpm.el="Windows", _xlpm.unit="Visible Transmittance"), Raw_envelope!$J:$J, "" ), _xlpm.r, _xlfn.XMATCH(1,(_xlpm.rCZ=_xlpm.cz)*(_xlpm.rV=_xlpm.v),0), IFERROR(INDEX(_xlpm.col,_xlpm.r),"") )} -> 0.061 | M5: {=_xlfn.LET( _xlpm.cz, M$2, _xlpm.v, $F5, _xlpm.el, $A5, _xlpm.unit, $E5, _xlpm.rCZ, Raw_envelope!$A:$A, _xlpm.rV, Raw_envelope!$B:$B, _xlpm.col, _xlfn.SWITCH(TRUE, AND(_xlpm.el="External Wall", _xlpm.unit="U-value IP"), Raw_envelope!$F:$F, AND(_xlpm.el="Roof", _xlpm.unit="U-value IP"), Raw_envelope!$D:$D, AND(_xlpm.el="Windows", _xlpm.unit="U-value IP"), Raw_envelope!$H:$H, AND(_xlpm.el="Windows", _xlpm.unit="SHGC"), Raw_envelope!$I:$I, AND(_xlpm.el="Windows", _xlpm.unit="Visible Transmittance"), Raw_envelope!$J:$J, "" ), _xlpm.r, _xlfn.XMATCH(1,(_xlpm.rCZ=_xlpm.cz)*(_xlpm.rV=_xlpm.v),0), IFERROR(INDEX(_xlpm.col,_xlpm.r),"") )} -> 0.061 | N5: {=_xlfn.LET( _xlpm.cz, N$2, _xlpm.v, $F5, _xlpm.el, $A5, _xlpm.unit, $E5, _xlpm.rCZ, Raw_envelope!$A:$A, _xlpm.rV, Raw_envelope!$B:$B, _xlpm.col, _xlfn.SWITCH(TRUE, AND(_xlpm.el="External Wall", _xlpm.unit="U-value IP"), Raw_envelope!$F:$F, AND(_xlpm.el="Roof", _xlpm.unit="U-value IP"), Raw_envelope!$D:$D, AND(_xlpm.el="Windows", _xlpm.unit="U-value IP"), Raw_envelope!$H:$H, AND(_xlpm.el="Windows", _xlpm.unit="SHGC"), Raw_envelope!$I:$I, AND(_xlpm.el="Windows", _xlpm.unit="Visible Transmittance"), Raw_envelope!$J:$J, "" ), _xlpm.r, _xlfn.XMATCH(1,(_xlpm.rCZ=_xlpm.cz)*(_xlpm.rV=_xlpm.v),0), IFERROR(INDEX(_xlpm.col,_xlpm.r),"") )} -> 0.065 | O5: {=_xlfn.LET( _xlpm.cz, O$2, _xlpm.v, $F5, _xlpm.el, $A5, _xlpm.unit, $E5, _xlpm.rCZ, Raw_envelope!$A:$A, _xlpm.rV, Raw_envelope!$B:$B, _xlpm.col, _xlfn.SWITCH(TRUE, AND(_xlpm.el="External Wall", _xlpm.unit="U-value IP"), Raw_envelope!$F:$F, AND(_xlpm.el="Roof", _xlpm.unit="U-value IP"), Raw_envelope!$D:$D, AND(_xlpm.el="Windows", _xlpm.unit="U-value IP"), Raw_envelope!$H:$H, AND(_xlpm.el="Windows", _xlpm.unit="SHGC"), Raw_envelope!$I:$I, AND(_xlpm.el="Windows", _xlpm.unit="Visible Transmittance"), Raw_envelope!$J:$J, "" ), _xlpm.r, _xlfn.XMATCH(1,(_xlpm.rCZ=_xlpm.cz)*(_xlpm.rV=_xlpm.v),0), IFERROR(INDEX(_xlpm.col,_xlpm.r),"") )} -> 0.065 | P5: {=_xlfn.LET( _xlpm.cz, P$2, _xlpm.v, $F5, _xlpm.el, $A5, _xlpm.unit, $E5, _xlpm.rCZ, Raw_envelope!$A:$A, _xlpm.rV, Raw_envelope!$B:$B, _xlpm.col, _xlfn.SWITCH(TRUE, AND(_xlpm.el="External Wall", _xlpm.unit="U-value IP"), Raw_envelope!$F:$F, AND(_xlpm.el="Roof", _xlpm.unit="U-value IP"), Raw_envelope!$D:$D, AND(_xlpm.el="Windows", _xlpm.unit="U-value IP"), Raw_envelope!$H:$H, AND(_xlpm.el="Windows", _xlpm.unit="SHGC"), Raw_envelope!$I:$I, AND(_xlpm.el="Windows", _xlpm.unit="Visible Transmittance"), Raw_envelope!$J:$J, "" ), _xlpm.r, _xlfn.XMATCH(1,(_xlpm.rCZ=_xlpm.cz)*(_xlpm.rV=_xlpm.v),0), IFERROR(INDEX(_xlpm.col,_xlpm.r),"") )} -> 0.065 | ... X5: {=_xlfn.LET( _xlpm.cz, X$2, _xlpm.v, $F5, _xlpm.el, $A5, _xlpm.unit, $E5, _xlpm.rCZ, Raw_envelope!$A:$A, _xlpm.rV, Raw_envelope!$B:$B, _xlpm.col, _xlfn.SWITCH(TRUE, AND(_xlpm.el="External Wall", _xlpm.unit="U-value IP"), Raw_envelope!$F:$F, AND(_xlpm.el="Roof", _xlpm.unit="U-value IP"), Raw_envelope!$D:$D, AND(_xlpm.el="Windows", _xlpm.unit="U-value IP"), Raw_envelope!$H:$H, AND(_xlpm.el="Windows", _xlpm.unit="SHGC"), Raw_envelope!$I:$I, AND(_xlpm.el="Windows", _xlpm.unit="Visible Transmittance"), Raw_envelope!$J:$J, "" ), _xlpm.r, _xlfn.XMATCH(1,(_xlpm.rCZ=_xlpm.cz)*(_xlpm.rV=_xlpm.v),0), IFERROR(INDEX(_xlpm.col,_xlpm.r),"") )} -> 0.06
