Workbook

Sheet Design flow rate
A1: Tech ID | B1: NE-Chiller-PumpCtrl-Full-Std | V1: Water density
B2: Design Flow Rate
B3: Existing Building | S3: CW Design Flow Rate (constant) (m3/s) | V3: 995 | W3: kg/m3
B4: Building Type | C4: CZ01 | D4: CZ02 | E4: CZ03 | F4: CZ04 | G4: CZ05 | H4: CZ06 | I4: CZ07 | J4: CZ08 | K4: CZ09 | L4: CZ10 | M4: CZ11 | N4: CZ12 | O4: CZ13 | P4: CZ14 | Q4: CZ15 | R4: CZ16 | S4: Min Across All CZ | T4: Average Across All CZ2 | U4: Max Across All CZ3
B5: ECC | C5: =IFERROR( _xlfn.MINIFS( 'Combined Runs'!$P:$P, 'Combined Runs'!$K:$K, C$4, 'Combined Runs'!$J:$J, "*" & $B5 & "&0&cPVVE&Ex&Chiller__PumpCtrl*" ), "" ) -> 0.139982 | D5: =IFERROR( _xlfn.MINIFS( 'Combined Runs'!$P:$P, 'Combined Runs'!$K:$K, D$4, 'Combined Runs'!$J:$J, "*" & $B5 & "&0&cPVVE&Ex&Chiller__PumpCtrl*" ), "" ) -> 0.179993 | E5: =IFERROR( _xlfn.MINIFS( 'Combined Runs'!$P:$P, 'Combined Runs'!$K:$K, E$4, 'Combined Runs'!$J:$J, "*" & $B5 & "&0&cPVVE&Ex&Chiller__PumpCtrl*" ), "" ) -> 0.169174 | F5: =IFERROR( _xlfn.MINIFS( 'Combined Runs'!$P:$P, 'Combined Runs'!$K:$K, F$4, 'Combined Runs'!$J:$J, "*" & $B5 & "&0&cPVVE&Ex&Chiller__PumpCtrl*" ), "" ) -> 0.182252 | G5: =IFERROR( _xlfn.MINIFS( 'Combined Runs'!$P:$P, 'Combined Runs'!$K:$K, G$4, 'Combined Runs'!$J:$J, "*" & $B5 & "&0&cPVVE&Ex&Chiller__PumpCtrl*" ), "" ) -> 0.159905 | H5: =IFERROR( _xlfn.MINIFS( 'Combined Runs'!$P:$P, 'Combined Runs'!$K:$K, H$4, 'Combined Runs'!$J:$J, "*" & $B5 & "&0&cPVVE&Ex&Chiller__PumpCtrl*" ), "" ) -> 0.166729 | I5: =IFERROR( _xlfn.MINIFS( 'Combined Runs'!$P:$P, 'Combined Runs'!$K:$K, I$4, 'Combined Runs'!$J:$J, "*" & $B5 & "&0&cPVVE&Ex&Chiller__PumpCtrl*" ), "" ) -> 0.170988 | J5: =IFERROR( _xlfn.MINIFS( 'Combined Runs'!$P:$P, 'Combined Runs'!$K:$K, J$4, 'Combined Runs'!$J:$J, "*" & $B5 & "&0&cPVVE&Ex&Chiller__PumpCtrl*" ), "" ) -> 0.183533 | ... R5: =IFERROR( _xlfn.MINIFS( 'Combined Runs'!$P:$P, 'Combined Runs'!$K:$K, R$4, 'Combined Runs'!$J:$J, "*" & $B5 & "&0&cPVVE&Ex&Chiller__PumpCtrl*" ), "" ) -> 0.177962 | S5: =MIN(Table2[[#This Row],[CZ01]:[CZ16]]) -> 0.139982 | T5: =AVERAGE(Table2[[#This Row],[CZ01]:[CZ16]]) -> 0.18315019 | U5: =MAX(Table2[[#This Row],[CZ01]:[CZ16]]) -> 0.209815
B6: Ese | C6: =IFERROR( _xlfn.MINIFS( 'Combined Runs'!$P:$P, 'Combined Runs'!$K:$K, C$4, 'Combined Runs'!$J:$J, "*" & $B6 & "&0&cPVVE&Ex&Chiller__PumpCtrl*" ), "" ) -> 0.023235 | D6: =IFERROR( _xlfn.MINIFS( 'Combined Runs'!$P:$P, 'Combined Runs'!$K:$K, D$4, 'Combined Runs'!$J:$J, "*" & $B6 & "&0&cPVVE&Ex&Chiller__PumpCtrl*" ), "" ) -> 0.029837 | E6: =IFERROR( _xlfn.MINIFS( 'Combined Runs'!$P:$P, 'Combined Runs'!$K:$K, E$4, 'Combined Runs'!$J:$J, "*" & $B6 & "&0&cPVVE&Ex&Chiller__PumpCtrl*" ), "" ) -> 0.028304 | F6: =IFERROR( _xlfn.MINIFS( 'Combined Runs'!$P:$P, 'Combined Runs'!$K:$K, F$4, 'Combined Runs'!$J:$J, "*" & $B6 & "&0&cPVVE&Ex&Chiller__PumpCtrl*" ), "" ) -> 0.030299 | G6: =IFERROR( _xlfn.MINIFS( 'Combined Runs'!$P:$P, 'Combined Runs'!$K:$K, G$4, 'Combined Runs'!$J:$J, "*" & $B6 & "&0&cPVVE&Ex&Chiller__PumpCtrl*" ), "" ) -> 0.026648 | H6: =IFERROR( _xlfn.MINIFS( 'Combined Runs'!$P:$P, 'Combined Runs'!$K:$K, H$4, 'Combined Runs'!$J:$J, "*" & $B6 & "&0&cPVVE&Ex&Chiller__PumpCtrl*" ), "" ) -> 0.027891 | I6: =IFERROR( _xlfn.MINIFS( 'Combined Runs'!$P:$P, 'Combined Runs'!$K:$K, I$4, 'Combined Runs'!$J:$J, "*" & $B6 & "&0&cPVVE&Ex&Chiller__PumpCtrl*" ), "" ) -> 0.028581 | J6: =IFERROR( _xlfn.MINIFS( 'Combined Runs'!$P:$P, 'Combined Runs'!$K:$K, J$4, 'Combined Runs'!$J:$J, "*" & $B6 & "&0&cPVVE&Ex&Chiller__PumpCtrl*" ), "" ) -> 0.03056 | ... R6: =IFERROR( _xlfn.MINIFS( 'Combined Runs'!$P:$P, 'Combined Runs'!$K:$K, R$4, 'Combined Runs'!$J:$J, "*" & $B6 & "&0&cPVVE&Ex&Chiller__PumpCtrl*" ), "" ) -> 0.028822 | S6: =MIN(Table2[[#This Row],[CZ01]:[CZ16]]) -> 0.023235 | T6: =AVERAGE(Table2[[#This Row],[CZ01]:[CZ16]]) -> 0.030174062 | U6: =MAX(Table2[[#This Row],[CZ01]:[CZ16]]) -> 0.034018
B7: Eun | C7: =IFERROR( _xlfn.MINIFS( 'Combined Runs'!$P:$P, 'Combined Runs'!$K:$K, C$4, 'Combined Runs'!$J:$J, "*" & $B7 & "&0&cPVVE&Ex&Chiller__PumpCtrl*" ), "" ) -> 0.358268 | D7: =IFERROR( _xlfn.MINIFS( 'Combined Runs'!$P:$P, 'Combined Runs'!$K:$K, D$4, 'Combined Runs'!$J:$J, "*" & $B7 & "&0&cPVVE&Ex&Chiller__PumpCtrl*" ), "" ) -> 0.424911 | E7: =IFERROR( _xlfn.MINIFS( 'Combined Runs'!$P:$P, 'Combined Runs'!$K:$K, E$4, 'Combined Runs'!$J:$J, "*" & $B7 & "&0&cPVVE&Ex&Chiller__PumpCtrl*" ), "" ) -> 0.411031 | F7: =IFERROR( _xlfn.MINIFS( 'Combined Runs'!$P:$P, 'Combined Runs'!$K:$K, F$4, 'Combined Runs'!$J:$J, "*" & $B7 & "&0&cPVVE&Ex&Chiller__PumpCtrl*" ), "" ) -> 0.428877 | G7: =IFERROR( _xlfn.MINIFS( 'Combined Runs'!$P:$P, 'Combined Runs'!$K:$K, G$4, 'Combined Runs'!$J:$J, "*" & $B7 & "&0&cPVVE&Ex&Chiller__PumpCtrl*" ), "" ) -> 0.39022 | H7: =IFERROR( _xlfn.MINIFS( 'Combined Runs'!$P:$P, 'Combined Runs'!$K:$K, H$4, 'Combined Runs'!$J:$J, "*" & $B7 & "&0&cPVVE&Ex&Chiller__PumpCtrl*" ), "" ) -> 0.402318 | I7: =IFERROR( _xlfn.MINIFS( 'Combined Runs'!$P:$P, 'Combined Runs'!$K:$K, I$4, 'Combined Runs'!$J:$J, "*" & $B7 & "&0&cPVVE&Ex&Chiller__PumpCtrl*" ), "" ) -> 0.409715 | J7: =IFERROR( _xlfn.MINIFS( 'Combined Runs'!$P:$P, 'Combined Runs'!$K:$K, J$4, 'Combined Runs'!$J:$J, "*" & $B7 & "&0&cPVVE&Ex&Chiller__PumpCtrl*" ), "" ) -> 0.431776 | ... R7: =IFERROR( _xlfn.MINIFS( 'Combined Runs'!$P:$P, 'Combined Runs'!$K:$K, R$4, 'Combined Runs'!$J:$J, "*" & $B7 & "&0&cPVVE&Ex&Chiller__PumpCtrl*" ), "" ) -> 0.417789 | S7: =MIN(Table2[[#This Row],[CZ01]:[CZ16]]) -> 0.358268 | T7: =AVERAGE(Table2[[#This Row],[CZ01]:[CZ16]]) -> 0.42854775 | U7: =MAX(Table2[[#This Row],[CZ01]:[CZ16]]) -> 0.471013
B8: Hsp | C8: =IFERROR( _xlfn.MINIFS( 'Combined Runs'!$P:$P, 'Combined Runs'!$K:$K, C$4, 'Combined Runs'!$J:$J, "*" & $B8 & "&0&cPVVE&Ex&Chiller__PumpCtrl*" ), "" ) -> 0.167969 | D8: =IFERROR( _xlfn.MINIFS( 'Combined Runs'!$P:$P, 'Combined Runs'!$K:$K, D$4, 'Combined Runs'!$J:$J, "*" & $B8 & "&0&cPVVE&Ex&Chiller__PumpCtrl*" ), "" ) -> 0.206671 | E8: =IFERROR( _xlfn.MINIFS( 'Combined Runs'!$P:$P, 'Combined Runs'!$K:$K, E$4, 'Combined Runs'!$J:$J, "*" & $B8 & "&0&cPVVE&Ex&Chiller__PumpCtrl*" ), "" ) -> 0.196562 | F8: =IFERROR( _xlfn.MINIFS( 'Combined Runs'!$P:$P, 'Combined Runs'!$K:$K, F$4, 'Combined Runs'!$J:$J, "*" & $B8 & "&0&cPVVE&Ex&Chiller__PumpCtrl*" ), "" ) -> 0.209419 | G8: =IFERROR( _xlfn.MINIFS( 'Combined Runs'!$P:$P, 'Combined Runs'!$K:$K, G$4, 'Combined Runs'!$J:$J, "*" & $B8 & "&0&cPVVE&Ex&Chiller__PumpCtrl*" ), "" ) -> 0.189554 | H8: =IFERROR( _xlfn.MINIFS( 'Combined Runs'!$P:$P, 'Combined Runs'!$K:$K, H$4, 'Combined Runs'!$J:$J, "*" & $B8 & "&0&cPVVE&Ex&Chiller__PumpCtrl*" ), "" ) -> 0.197252 | I8: =IFERROR( _xlfn.MINIFS( 'Combined Runs'!$P:$P, 'Combined Runs'!$K:$K, I$4, 'Combined Runs'!$J:$J, "*" & $B8 & "&0&cPVVE&Ex&Chiller__PumpCtrl*" ), "" ) -> 0.202138 | J8: =IFERROR( _xlfn.MINIFS( 'Combined Runs'!$P:$P, 'Combined Runs'!$K:$K, J$4, 'Combined Runs'!$J:$J, "*" & $B8 & "&0&cPVVE&Ex&Chiller__PumpCtrl*" ), "" ) -> 0.212416 | ... R8: =IFERROR( _xlfn.MINIFS( 'Combined Runs'!$P:$P, 'Combined Runs'!$K:$K, R$4, 'Combined Runs'!$J:$J, "*" & $B8 & "&0&cPVVE&Ex&Chiller__PumpCtrl*" ), "" ) -> 0.207249 | S8: =MIN(Table2[[#This Row],[CZ01]:[CZ16]]) -> 0.167969 | T8: =AVERAGE(Table2[[#This Row],[CZ01]:[CZ16]]) -> 0.21134369 | U8: =MAX(Table2[[#This Row],[CZ01]:[CZ16]]) -> 0.236115
B9: Nrs | C9: =IFERROR( _xlfn.MINIFS( 'Combined Runs'!$P:$P, 'Combined Runs'!$K:$K, C$4, 'Combined Runs'!$J:$J, "*" & $B9 & "&0&cPVVE&Ex&Chiller__PumpCtrl*" ), "" ) -> 0.021413 | D9: =IFERROR( _xlfn.MINIFS( 'Combined Runs'!$P:$P, 'Combined Runs'!$K:$K, D$4, 'Combined Runs'!$J:$J, "*" & $B9 & "&0&cPVVE&Ex&Chiller__PumpCtrl*" ), "" ) -> 0.027234 | E9: =IFERROR( _xlfn.MINIFS( 'Combined Runs'!$P:$P, 'Combined Runs'!$K:$K, E$4, 'Combined Runs'!$J:$J, "*" & $B9 & "&0&cPVVE&Ex&Chiller__PumpCtrl*" ), "" ) -> 0.025771 | F9: =IFERROR( _xlfn.MINIFS( 'Combined Runs'!$P:$P, 'Combined Runs'!$K:$K, F$4, 'Combined Runs'!$J:$J, "*" & $B9 & "&0&cPVVE&Ex&Chiller__PumpCtrl*" ), "" ) -> 0.027591 | G9: =IFERROR( _xlfn.MINIFS( 'Combined Runs'!$P:$P, 'Combined Runs'!$K:$K, G$4, 'Combined Runs'!$J:$J, "*" & $B9 & "&0&cPVVE&Ex&Chiller__PumpCtrl*" ), "" ) -> 0.024224 | H9: =IFERROR( _xlfn.MINIFS( 'Combined Runs'!$P:$P, 'Combined Runs'!$K:$K, H$4, 'Combined Runs'!$J:$J, "*" & $B9 & "&0&cPVVE&Ex&Chiller__PumpCtrl*" ), "" ) -> 0.025254 | I9: =IFERROR( _xlfn.MINIFS( 'Combined Runs'!$P:$P, 'Combined Runs'!$K:$K, I$4, 'Combined Runs'!$J:$J, "*" & $B9 & "&0&cPVVE&Ex&Chiller__PumpCtrl*" ), "" ) -> 0.025727 | J9: =IFERROR( _xlfn.MINIFS( 'Combined Runs'!$P:$P, 'Combined Runs'!$K:$K, J$4, 'Combined Runs'!$J:$J, "*" & $B9 & "&0&cPVVE&Ex&Chiller__PumpCtrl*" ), "" ) -> 0.027683 | ... R9: =IFERROR( _xlfn.MINIFS( 'Combined Runs'!$P:$P, 'Combined Runs'!$K:$K, R$4, 'Combined Runs'!$J:$J, "*" & $B9 & "&0&cPVVE&Ex&Chiller__PumpCtrl*" ), "" ) -> 0.026836 | S9: =MIN(Table2[[#This Row],[CZ01]:[CZ16]]) -> 0.021413 | T9: =AVERAGE(Table2[[#This Row],[CZ01]:[CZ16]]) -> 0.027555812 | U9: =MAX(Table2[[#This Row],[CZ01]:[CZ16]]) -> 0.031352
B10: OfL | C10: =IFERROR( _xlfn.MINIFS( 'Combined Runs'!$P:$P, 'Combined Runs'!$K:$K, C$4, 'Combined Runs'!$J:$J, "*" & $B10 & "&0&cPVVE&Ex&Chiller__PumpCtrl*" ), "" ) -> 0.13852 | D10: =IFERROR( _xlfn.MINIFS( 'Combined Runs'!$P:$P, 'Combined Runs'!$K:$K, D$4, 'Combined Runs'!$J:$J, "*" & $B10 & "&0&cPVVE&Ex&Chiller__PumpCtrl*" ), "" ) -> 0.172606 | E10: =IFERROR( _xlfn.MINIFS( 'Combined Runs'!$P:$P, 'Combined Runs'!$K:$K, E$4, 'Combined Runs'!$J:$J, "*" & $B10 & "&0&cPVVE&Ex&Chiller__PumpCtrl*" ), "" ) -> 0.163161 | F10: =IFERROR( _xlfn.MINIFS( 'Combined Runs'!$P:$P, 'Combined Runs'!$K:$K, F$4, 'Combined Runs'!$J:$J, "*" & $B10 & "&0&cPVVE&Ex&Chiller__PumpCtrl*" ), "" ) -> 0.173778 | G10: =IFERROR( _xlfn.MINIFS( 'Combined Runs'!$P:$P, 'Combined Runs'!$K:$K, G$4, 'Combined Runs'!$J:$J, "*" & $B10 & "&0&cPVVE&Ex&Chiller__PumpCtrl*" ), "" ) -> 0.157707 | H10: =IFERROR( _xlfn.MINIFS( 'Combined Runs'!$P:$P, 'Combined Runs'!$K:$K, H$4, 'Combined Runs'!$J:$J, "*" & $B10 & "&0&cPVVE&Ex&Chiller__PumpCtrl*" ), "" ) -> 0.15958 | I10: =IFERROR( _xlfn.MINIFS( 'Combined Runs'!$P:$P, 'Combined Runs'!$K:$K, I$4, 'Combined Runs'!$J:$J, "*" & $B10 & "&0&cPVVE&Ex&Chiller__PumpCtrl*" ), "" ) -> 0.16061 | J10: =IFERROR( _xlfn.MINIFS( 'Combined Runs'!$P:$P, 'Combined Runs'!$K:$K, J$4, 'Combined Runs'!$J:$J, "*" & $B10 & "&0&cPVVE&Ex&Chiller__PumpCtrl*" ), "" ) -> 0.172795 | ... R10: =IFERROR( _xlfn.MINIFS( 'Combined Runs'!$P:$P, 'Combined Runs'!$K:$K, R$4, 'Combined Runs'!$J:$J, "*" & $B10 & "&0&cPVVE&Ex&Chiller__PumpCtrl*" ), "" ) -> 0.17327 | S10: =MIN(Table2[[#This Row],[CZ01]:[CZ16]]) -> 0.13852 | T10: =AVERAGE(Table2[[#This Row],[CZ01]:[CZ16]]) -> 0.17218594 | U10: =MAX(Table2[[#This Row],[CZ01]:[CZ16]]) -> 0.189932
B11: OfS | C11: =IFERROR( _xlfn.MINIFS( 'Combined Runs'!$P:$P, 'Combined Runs'!$K:$K, C$4, 'Combined Runs'!$J:$J, "*" & $B11 & "&0&cPVVE&Ex&Chiller__PumpCtrl*" ), "" ) -> 0.010408 | D11: =IFERROR( _xlfn.MINIFS( 'Combined Runs'!$P:$P, 'Combined Runs'!$K:$K, D$4, 'Combined Runs'!$J:$J, "*" & $B11 & "&0&cPVVE&Ex&Chiller__PumpCtrl*" ), "" ) -> 0.01296 | E11: =IFERROR( _xlfn.MINIFS( 'Combined Runs'!$P:$P, 'Combined Runs'!$K:$K, E$4, 'Combined Runs'!$J:$J, "*" & $B11 & "&0&cPVVE&Ex&Chiller__PumpCtrl*" ), "" ) -> 0.012449 | F11: =IFERROR( _xlfn.MINIFS( 'Combined Runs'!$P:$P, 'Combined Runs'!$K:$K, F$4, 'Combined Runs'!$J:$J, "*" & $B11 & "&0&cPVVE&Ex&Chiller__PumpCtrl*" ), "" ) -> 0.013129 | G11: =IFERROR( _xlfn.MINIFS( 'Combined Runs'!$P:$P, 'Combined Runs'!$K:$K, G$4, 'Combined Runs'!$J:$J, "*" & $B11 & "&0&cPVVE&Ex&Chiller__PumpCtrl*" ), "" ) -> 0.011868 | H11: =IFERROR( _xlfn.MINIFS( 'Combined Runs'!$P:$P, 'Combined Runs'!$K:$K, H$4, 'Combined Runs'!$J:$J, "*" & $B11 & "&0&cPVVE&Ex&Chiller__PumpCtrl*" ), "" ) -> 0.012127 | I11: =IFERROR( _xlfn.MINIFS( 'Combined Runs'!$P:$P, 'Combined Runs'!$K:$K, I$4, 'Combined Runs'!$J:$J, "*" & $B11 & "&0&cPVVE&Ex&Chiller__PumpCtrl*" ), "" ) -> 0.012135 | J11: =IFERROR( _xlfn.MINIFS( 'Combined Runs'!$P:$P, 'Combined Runs'!$K:$K, J$4, 'Combined Runs'!$J:$J, "*" & $B11 & "&0&cPVVE&Ex&Chiller__PumpCtrl*" ), "" ) -> 0.013076 | ... R11: =IFERROR( _xlfn.MINIFS( 'Combined Runs'!$P:$P, 'Combined Runs'!$K:$K, R$4, 'Combined Runs'!$J:$J, "*" & $B11 & "&0&cPVVE&Ex&Chiller__PumpCtrl*" ), "" ) -> 0.012972 | S11: =MIN(Table2[[#This Row],[CZ01]:[CZ16]]) -> 0.010408 | T11: =AVERAGE(Table2[[#This Row],[CZ01]:[CZ16]]) -> 0.012936375 | U11: =MAX(Table2[[#This Row],[CZ01]:[CZ16]]) -> 0.014157
B12: Rt3 | C12: =IFERROR( _xlfn.MINIFS( 'Combined Runs'!$P:$P, 'Combined Runs'!$K:$K, C$4, 'Combined Runs'!$J:$J, "*" & $B12 & "&0&cPVVE&Ex&Chiller__PumpCtrl*" ), "" ) -> 0.091895 | D12: =IFERROR( _xlfn.MINIFS( 'Combined Runs'!$P:$P, 'Combined Runs'!$K:$K, D$4, 'Combined Runs'!$J:$J, "*" & $B12 & "&0&cPVVE&Ex&Chiller__PumpCtrl*" ), "" ) -> 0.122211 | E12: =IFERROR( _xlfn.MINIFS( 'Combined Runs'!$P:$P, 'Combined Runs'!$K:$K, E$4, 'Combined Runs'!$J:$J, "*" & $B12 & "&0&cPVVE&Ex&Chiller__PumpCtrl*" ), "" ) -> 0.115581 | F12: =IFERROR( _xlfn.MINIFS( 'Combined Runs'!$P:$P, 'Combined Runs'!$K:$K, F$4, 'Combined Runs'!$J:$J, "*" & $B12 & "&0&cPVVE&Ex&Chiller__PumpCtrl*" ), "" ) -> 0.12519 | G12: =IFERROR( _xlfn.MINIFS( 'Combined Runs'!$P:$P, 'Combined Runs'!$K:$K, G$4, 'Combined Runs'!$J:$J, "*" & $B12 & "&0&cPVVE&Ex&Chiller__PumpCtrl*" ), "" ) -> 0.109951 | H12: =IFERROR( _xlfn.MINIFS( 'Combined Runs'!$P:$P, 'Combined Runs'!$K:$K, H$4, 'Combined Runs'!$J:$J, "*" & $B12 & "&0&cPVVE&Ex&Chiller__PumpCtrl*" ), "" ) -> 0.117493 | I12: =IFERROR( _xlfn.MINIFS( 'Combined Runs'!$P:$P, 'Combined Runs'!$K:$K, I$4, 'Combined Runs'!$J:$J, "*" & $B12 & "&0&cPVVE&Ex&Chiller__PumpCtrl*" ), "" ) -> 0.122761 | J12: =IFERROR( _xlfn.MINIFS( 'Combined Runs'!$P:$P, 'Combined Runs'!$K:$K, J$4, 'Combined Runs'!$J:$J, "*" & $B12 & "&0&cPVVE&Ex&Chiller__PumpCtrl*" ), "" ) -> 0.128477 | ... R12: =IFERROR( _xlfn.MINIFS( 'Combined Runs'!$P:$P, 'Combined Runs'!$K:$K, R$4, 'Combined Runs'!$J:$J, "*" & $B12 & "&0&cPVVE&Ex&Chiller__PumpCtrl*" ), "" ) -> 0.117654 | S12: =MIN(Table2[[#This Row],[CZ01]:[CZ16]]) -> 0.091895 | T12: =AVERAGE(Table2[[#This Row],[CZ01]:[CZ16]]) -> 0.1259815 | U12: =MAX(Table2[[#This Row],[CZ01]:[CZ16]]) -> 0.144495
B13: Htl | C13: =IFERROR( _xlfn.MINIFS( 'Combined Runs'!$P:$P, 'Combined Runs'!$K:$K, C$4, 'Combined Runs'!$J:$J, "*" & $B13 & "&0&cPVVE&Ex&Chiller__PumpCtrl*" ), "" ) -> 0.017149 | D13: =IFERROR( _xlfn.MINIFS( 'Combined Runs'!$P:$P, 'Combined Runs'!$K:$K, D$4, 'Combined Runs'!$J:$J, "*" & $B13 & "&0&cPVVE&Ex&Chiller__PumpCtrl*" ), "" ) -> 0.022915 | E13: =IFERROR( _xlfn.MINIFS( 'Combined Runs'!$P:$P, 'Combined Runs'!$K:$K, E$4, 'Combined Runs'!$J:$J, "*" & $B13 & "&0&cPVVE&Ex&Chiller__PumpCtrl*" ), "" ) -> 0.021574 | F13: =IFERROR( _xlfn.MINIFS( 'Combined Runs'!$P:$P, 'Combined Runs'!$K:$K, F$4, 'Combined Runs'!$J:$J, "*" & $B13 & "&0&cPVVE&Ex&Chiller__PumpCtrl*" ), "" ) -> 0.023235 | G13: =IFERROR( _xlfn.MINIFS( 'Combined Runs'!$P:$P, 'Combined Runs'!$K:$K, G$4, 'Combined Runs'!$J:$J, "*" & $B13 & "&0&cPVVE&Ex&Chiller__PumpCtrl*" ), "" ) -> 0.01989 | H13: =IFERROR( _xlfn.MINIFS( 'Combined Runs'!$P:$P, 'Combined Runs'!$K:$K, H$4, 'Combined Runs'!$J:$J, "*" & $B13 & "&0&cPVVE&Ex&Chiller__PumpCtrl*" ), "" ) -> 0.020983 | I13: =IFERROR( _xlfn.MINIFS( 'Combined Runs'!$P:$P, 'Combined Runs'!$K:$K, I$4, 'Combined Runs'!$J:$J, "*" & $B13 & "&0&cPVVE&Ex&Chiller__PumpCtrl*" ), "" ) -> 0.021398 | J13: =IFERROR( _xlfn.MINIFS( 'Combined Runs'!$P:$P, 'Combined Runs'!$K:$K, J$4, 'Combined Runs'!$J:$J, "*" & $B13 & "&0&cPVVE&Ex&Chiller__PumpCtrl*" ), "" ) -> 0.023476 | ... R13: =IFERROR( _xlfn.MINIFS( 'Combined Runs'!$P:$P, 'Combined Runs'!$K:$K, R$4, 'Combined Runs'!$J:$J, "*" & $B13 & "&0&cPVVE&Ex&Chiller__PumpCtrl*" ), "" ) -> 0.023196 | S13: =MIN(Table2[[#This Row],[CZ01]:[CZ16]]) -> 0.017149 | T13: =AVERAGE(Table2[[#This Row],[CZ01]:[CZ16]]) -> 0.023511437 | U13: =MAX(Table2[[#This Row],[CZ01]:[CZ16]]) -> 0.027526
B16: New Building | S16: CW Design Flow Rate (constant) (m3/s)
B17: Building Type | C17: CZ01 | D17: CZ02 | E17: CZ03 | F17: CZ04 | G17: CZ05 | H17: CZ06 | I17: CZ07 | J17: CZ08 | K17: CZ09 | L17: CZ10 | M17: CZ11 | N17: CZ12 | O17: CZ13 | P17: CZ14 | Q17: CZ15 | R17: CZ16 | S17: Min Across All CZ | T17: Average Across All CZ2 | U17: Max Across All CZ3
B18: ECC | C18: =IFERROR( _xlfn.MINIFS( 'Combined Runs'!$P:$P, 'Combined Runs'!$K:$K, C$17, 'Combined Runs'!$J:$J, "*" & $B18 & "&0&cPVVE&New&Chiller__PumpCtrl*" ), "" ) -> 0.10838 | D18: =IFERROR( _xlfn.MINIFS( 'Combined Runs'!$P:$P, 'Combined Runs'!$K:$K, D$17, 'Combined Runs'!$J:$J, "*" & $B18 & "&0&cPVVE&New&Chiller__PumpCtrl*" ), "" ) -> 0.150994 | E18: =IFERROR( _xlfn.MINIFS( 'Combined Runs'!$P:$P, 'Combined Runs'!$K:$K, E$17, 'Combined Runs'!$J:$J, "*" & $B18 & "&0&cPVVE&New&Chiller__PumpCtrl*" ), "" ) -> 0.140111 | F18: =IFERROR( _xlfn.MINIFS( 'Combined Runs'!$P:$P, 'Combined Runs'!$K:$K, F$17, 'Combined Runs'!$J:$J, "*" & $B18 & "&0&cPVVE&New&Chiller__PumpCtrl*" ), "" ) -> 0.153114 | G18: =IFERROR( _xlfn.MINIFS( 'Combined Runs'!$P:$P, 'Combined Runs'!$K:$K, G$17, 'Combined Runs'!$J:$J, "*" & $B18 & "&0&cPVVE&New&Chiller__PumpCtrl*" ), "" ) -> 0.130863 | H18: =IFERROR( _xlfn.MINIFS( 'Combined Runs'!$P:$P, 'Combined Runs'!$K:$K, H$17, 'Combined Runs'!$J:$J, "*" & $B18 & "&0&cPVVE&New&Chiller__PumpCtrl*" ), "" ) -> 0.138835 | I18: =IFERROR( _xlfn.MINIFS( 'Combined Runs'!$P:$P, 'Combined Runs'!$K:$K, I$17, 'Combined Runs'!$J:$J, "*" & $B18 & "&0&cPVVE&New&Chiller__PumpCtrl*" ), "" ) -> 0.142779 | J18: =IFERROR( _xlfn.MINIFS( 'Combined Runs'!$P:$P, 'Combined Runs'!$K:$K, J$17, 'Combined Runs'!$J:$J, "*" & $B18 & "&0&cPVVE&New&Chiller__PumpCtrl*" ), "" ) -> 0.155472 | ... R18: =IFERROR( _xlfn.MINIFS( 'Combined Runs'!$P:$P, 'Combined Runs'!$K:$K, R$17, 'Combined Runs'!$J:$J, "*" & $B18 & "&0&cPVVE&New&Chiller__PumpCtrl*" ), "" ) -> 0.140826 | S18: =MIN(Table24[[#This Row],[CZ01]:[CZ16]]) -> 0.10838 | T18: =AVERAGE(Table24[[#This Row],[CZ01]:[CZ16]]) -> 0.14990988 | U18: =MAX(Table24[[#This Row],[CZ01]:[CZ16]]) -> 0.172093
B19: Ese | C19: =IFERROR( _xlfn.MINIFS( 'Combined Runs'!$P:$P, 'Combined Runs'!$K:$K, C$17, 'Combined Runs'!$J:$J, "*" & $B19 & "&0&cPVVE&New&Chiller__PumpCtrl*" ), "" ) -> 0.016484 | D19: =IFERROR( _xlfn.MINIFS( 'Combined Runs'!$P:$P, 'Combined Runs'!$K:$K, D$17, 'Combined Runs'!$J:$J, "*" & $B19 & "&0&cPVVE&New&Chiller__PumpCtrl*" ), "" ) -> 0.02371 | E19: =IFERROR( _xlfn.MINIFS( 'Combined Runs'!$P:$P, 'Combined Runs'!$K:$K, E$17, 'Combined Runs'!$J:$J, "*" & $B19 & "&0&cPVVE&New&Chiller__PumpCtrl*" ), "" ) -> 0.022182 | F19: =IFERROR( _xlfn.MINIFS( 'Combined Runs'!$P:$P, 'Combined Runs'!$K:$K, F$17, 'Combined Runs'!$J:$J, "*" & $B19 & "&0&cPVVE&New&Chiller__PumpCtrl*" ), "" ) -> 0.024118 | G19: =IFERROR( _xlfn.MINIFS( 'Combined Runs'!$P:$P, 'Combined Runs'!$K:$K, G$17, 'Combined Runs'!$J:$J, "*" & $B19 & "&0&cPVVE&New&Chiller__PumpCtrl*" ), "" ) -> 0.020516 | H19: =IFERROR( _xlfn.MINIFS( 'Combined Runs'!$P:$P, 'Combined Runs'!$K:$K, H$17, 'Combined Runs'!$J:$J, "*" & $B19 & "&0&cPVVE&New&Chiller__PumpCtrl*" ), "" ) -> 0.022175 | I19: =IFERROR( _xlfn.MINIFS( 'Combined Runs'!$P:$P, 'Combined Runs'!$K:$K, I$17, 'Combined Runs'!$J:$J, "*" & $B19 & "&0&cPVVE&New&Chiller__PumpCtrl*" ), "" ) -> 0.022815 | J19: =IFERROR( _xlfn.MINIFS( 'Combined Runs'!$P:$P, 'Combined Runs'!$K:$K, J$17, 'Combined Runs'!$J:$J, "*" & $B19 & "&0&cPVVE&New&Chiller__PumpCtrl*" ), "" ) -> 0.024768 | ... R19: =IFERROR( _xlfn.MINIFS( 'Combined Runs'!$P:$P, 'Combined Runs'!$K:$K, R$17, 'Combined Runs'!$J:$J, "*" & $B19 & "&0&cPVVE&New&Chiller__PumpCtrl*" ), "" ) -> 0.020577 | S19: =MIN(Table24[[#This Row],[CZ01]:[CZ16]]) -> 0.016484 | T19: =AVERAGE(Table24[[#This Row],[CZ01]:[CZ16]]) -> 0.023086438 | U19: =MAX(Table24[[#This Row],[CZ01]:[CZ16]]) -> 0.02698
B20: Eun | C20: =IFERROR( _xlfn.MINIFS( 'Combined Runs'!$P:$P, 'Combined Runs'!$K:$K, C$17, 'Combined Runs'!$J:$J, "*" & $B20 & "&0&cPVVE&New&Chiller__PumpCtrl*" ), "" ) -> 0.254686 | D20: =IFERROR( _xlfn.MINIFS( 'Combined Runs'!$P:$P, 'Combined Runs'!$K:$K, D$17, 'Combined Runs'!$J:$J, "*" & $B20 & "&0&cPVVE&New&Chiller__PumpCtrl*" ), "" ) -> 0.306028 | E20: =IFERROR( _xlfn.MINIFS( 'Combined Runs'!$P:$P, 'Combined Runs'!$K:$K, E$17, 'Combined Runs'!$J:$J, "*" & $B20 & "&0&cPVVE&New&Chiller__PumpCtrl*" ), "" ) -> 0.296517 | F20: =IFERROR( _xlfn.MINIFS( 'Combined Runs'!$P:$P, 'Combined Runs'!$K:$K, F$17, 'Combined Runs'!$J:$J, "*" & $B20 & "&0&cPVVE&New&Chiller__PumpCtrl*" ), "" ) -> 0.309351 | G20: =IFERROR( _xlfn.MINIFS( 'Combined Runs'!$P:$P, 'Combined Runs'!$K:$K, G$17, 'Combined Runs'!$J:$J, "*" & $B20 & "&0&cPVVE&New&Chiller__PumpCtrl*" ), "" ) -> 0.275403 | H20: =IFERROR( _xlfn.MINIFS( 'Combined Runs'!$P:$P, 'Combined Runs'!$K:$K, H$17, 'Combined Runs'!$J:$J, "*" & $B20 & "&0&cPVVE&New&Chiller__PumpCtrl*" ), "" ) -> 0.28924 | I20: =IFERROR( _xlfn.MINIFS( 'Combined Runs'!$P:$P, 'Combined Runs'!$K:$K, I$17, 'Combined Runs'!$J:$J, "*" & $B20 & "&0&cPVVE&New&Chiller__PumpCtrl*" ), "" ) -> 0.298919 | J20: =IFERROR( _xlfn.MINIFS( 'Combined Runs'!$P:$P, 'Combined Runs'!$K:$K, J$17, 'Combined Runs'!$J:$J, "*" & $B20 & "&0&cPVVE&New&Chiller__PumpCtrl*" ), "" ) -> 0.312317 | ... R20: =IFERROR( _xlfn.MINIFS( 'Combined Runs'!$P:$P, 'Combined Runs'!$K:$K, R$17, 'Combined Runs'!$J:$J, "*" & $B20 & "&0&cPVVE&New&Chiller__PumpCtrl*" ), "" ) -> 0.298478 | S20: =MIN(Table24[[#This Row],[CZ01]:[CZ16]]) -> 0.254686 | T20: =AVERAGE(Table24[[#This Row],[CZ01]:[CZ16]]) -> 0.31084813 | U20: =MAX(Table24[[#This Row],[CZ01]:[CZ16]]) -> 0.352529
B21: Hsp | C21: =IFERROR( _xlfn.MINIFS( 'Combined Runs'!$P:$P, 'Combined Runs'!$K:$K, C$17, 'Combined Runs'!$J:$J, "*" & $B21 & "&0&cPVVE&New&Chiller__PumpCtrl*" ), "" ) -> 0.142966 | D21: =IFERROR( _xlfn.MINIFS( 'Combined Runs'!$P:$P, 'Combined Runs'!$K:$K, D$17, 'Combined Runs'!$J:$J, "*" & $B21 & "&0&cPVVE&New&Chiller__PumpCtrl*" ), "" ) -> 0.192381 | E21: =IFERROR( _xlfn.MINIFS( 'Combined Runs'!$P:$P, 'Combined Runs'!$K:$K, E$17, 'Combined Runs'!$J:$J, "*" & $B21 & "&0&cPVVE&New&Chiller__PumpCtrl*" ), "" ) -> 0.180887 | F21: =IFERROR( _xlfn.MINIFS( 'Combined Runs'!$P:$P, 'Combined Runs'!$K:$K, F$17, 'Combined Runs'!$J:$J, "*" & $B21 & "&0&cPVVE&New&Chiller__PumpCtrl*" ), "" ) -> 0.194702 | G21: =IFERROR( _xlfn.MINIFS( 'Combined Runs'!$P:$P, 'Combined Runs'!$K:$K, G$17, 'Combined Runs'!$J:$J, "*" & $B21 & "&0&cPVVE&New&Chiller__PumpCtrl*" ), "" ) -> 0.173009 | H21: =IFERROR( _xlfn.MINIFS( 'Combined Runs'!$P:$P, 'Combined Runs'!$K:$K, H$17, 'Combined Runs'!$J:$J, "*" & $B21 & "&0&cPVVE&New&Chiller__PumpCtrl*" ), "" ) -> 0.181613 | I21: =IFERROR( _xlfn.MINIFS( 'Combined Runs'!$P:$P, 'Combined Runs'!$K:$K, I$17, 'Combined Runs'!$J:$J, "*" & $B21 & "&0&cPVVE&New&Chiller__PumpCtrl*" ), "" ) -> 0.184853 | J21: =IFERROR( _xlfn.MINIFS( 'Combined Runs'!$P:$P, 'Combined Runs'!$K:$K, J$17, 'Combined Runs'!$J:$J, "*" & $B21 & "&0&cPVVE&New&Chiller__PumpCtrl*" ), "" ) -> 0.198022 | ... R21: =IFERROR( _xlfn.MINIFS( 'Combined Runs'!$P:$P, 'Combined Runs'!$K:$K, R$17, 'Combined Runs'!$J:$J, "*" & $B21 & "&0&cPVVE&New&Chiller__PumpCtrl*" ), "" ) -> 0.173716 | S21: =MIN(Table24[[#This Row],[CZ01]:[CZ16]]) -> 0.142966 | T21: =AVERAGE(Table24[[#This Row],[CZ01]:[CZ16]]) -> 0.18707287 | U21: =MAX(Table24[[#This Row],[CZ01]:[CZ16]]) -> 0.214107
B22: Nrs | C22: =IFERROR( _xlfn.MINIFS( 'Combined Runs'!$P:$P, 'Combined Runs'!$K:$K, C$17, 'Combined Runs'!$J:$J, "*" & $B22 & "&0&cPVVE&New&Chiller__PumpCtrl*" ), "" ) -> 0.015308 | D22: =IFERROR( _xlfn.MINIFS( 'Combined Runs'!$P:$P, 'Combined Runs'!$K:$K, D$17, 'Combined Runs'!$J:$J, "*" & $B22 & "&0&cPVVE&New&Chiller__PumpCtrl*" ), "" ) -> 0.0197 | E22: =IFERROR( _xlfn.MINIFS( 'Combined Runs'!$P:$P, 'Combined Runs'!$K:$K, E$17, 'Combined Runs'!$J:$J, "*" & $B22 & "&0&cPVVE&New&Chiller__PumpCtrl*" ), "" ) -> 0.019036 | F22: =IFERROR( _xlfn.MINIFS( 'Combined Runs'!$P:$P, 'Combined Runs'!$K:$K, F$17, 'Combined Runs'!$J:$J, "*" & $B22 & "&0&cPVVE&New&Chiller__PumpCtrl*" ), "" ) -> 0.020029 | G22: =IFERROR( _xlfn.MINIFS( 'Combined Runs'!$P:$P, 'Combined Runs'!$K:$K, G$17, 'Combined Runs'!$J:$J, "*" & $B22 & "&0&cPVVE&New&Chiller__PumpCtrl*" ), "" ) -> 0.017631 | H22: =IFERROR( _xlfn.MINIFS( 'Combined Runs'!$P:$P, 'Combined Runs'!$K:$K, H$17, 'Combined Runs'!$J:$J, "*" & $B22 & "&0&cPVVE&New&Chiller__PumpCtrl*" ), "" ) -> 0.018833 | I22: =IFERROR( _xlfn.MINIFS( 'Combined Runs'!$P:$P, 'Combined Runs'!$K:$K, I$17, 'Combined Runs'!$J:$J, "*" & $B22 & "&0&cPVVE&New&Chiller__PumpCtrl*" ), "" ) -> 0.019461 | J22: =IFERROR( _xlfn.MINIFS( 'Combined Runs'!$P:$P, 'Combined Runs'!$K:$K, J$17, 'Combined Runs'!$J:$J, "*" & $B22 & "&0&cPVVE&New&Chiller__PumpCtrl*" ), "" ) -> 0.020815 | ... R22: =IFERROR( _xlfn.MINIFS( 'Combined Runs'!$P:$P, 'Combined Runs'!$K:$K, R$17, 'Combined Runs'!$J:$J, "*" & $B22 & "&0&cPVVE&New&Chiller__PumpCtrl*" ), "" ) -> 0.019782 | S22: =MIN(Table24[[#This Row],[CZ01]:[CZ16]]) -> 0.015308 | T22: =AVERAGE(Table24[[#This Row],[CZ01]:[CZ16]]) -> 0.020424125 | U22: =MAX(Table24[[#This Row],[CZ01]:[CZ16]]) -> 0.023675
B23: OfL | C23: =IFERROR( _xlfn.MINIFS( 'Combined Runs'!$P:$P, 'Combined Runs'!$K:$K, C$17, 'Combined Runs'!$J:$J, "*" & $B23 & "&0&cPVVE&New&Chiller__PumpCtrl*" ), "" ) -> 0.090241 | D23: =IFERROR( _xlfn.MINIFS( 'Combined Runs'!$P:$P, 'Combined Runs'!$K:$K, D$17, 'Combined Runs'!$J:$J, "*" & $B23 & "&0&cPVVE&New&Chiller__PumpCtrl*" ), "" ) -> 0.112632 | E23: =IFERROR( _xlfn.MINIFS( 'Combined Runs'!$P:$P, 'Combined Runs'!$K:$K, E$17, 'Combined Runs'!$J:$J, "*" & $B23 & "&0&cPVVE&New&Chiller__PumpCtrl*" ), "" ) -> 0.106831 | F23: =IFERROR( _xlfn.MINIFS( 'Combined Runs'!$P:$P, 'Combined Runs'!$K:$K, F$17, 'Combined Runs'!$J:$J, "*" & $B23 & "&0&cPVVE&New&Chiller__PumpCtrl*" ), "" ) -> 0.113262 | G23: =IFERROR( _xlfn.MINIFS( 'Combined Runs'!$P:$P, 'Combined Runs'!$K:$K, G$17, 'Combined Runs'!$J:$J, "*" & $B23 & "&0&cPVVE&New&Chiller__PumpCtrl*" ), "" ) -> 0.101248 | H23: =IFERROR( _xlfn.MINIFS( 'Combined Runs'!$P:$P, 'Combined Runs'!$K:$K, H$17, 'Combined Runs'!$J:$J, "*" & $B23 & "&0&cPVVE&New&Chiller__PumpCtrl*" ), "" ) -> 0.104863 | I23: =IFERROR( _xlfn.MINIFS( 'Combined Runs'!$P:$P, 'Combined Runs'!$K:$K, I$17, 'Combined Runs'!$J:$J, "*" & $B23 & "&0&cPVVE&New&Chiller__PumpCtrl*" ), "" ) -> 0.107166 | J23: =IFERROR( _xlfn.MINIFS( 'Combined Runs'!$P:$P, 'Combined Runs'!$K:$K, J$17, 'Combined Runs'!$J:$J, "*" & $B23 & "&0&cPVVE&New&Chiller__PumpCtrl*" ), "" ) -> 0.113846 | ... R23: =IFERROR( _xlfn.MINIFS( 'Combined Runs'!$P:$P, 'Combined Runs'!$K:$K, R$17, 'Combined Runs'!$J:$J, "*" & $B23 & "&0&cPVVE&New&Chiller__PumpCtrl*" ), "" ) -> 0.117335 | S23: =MIN(Table24[[#This Row],[CZ01]:[CZ16]]) -> 0.090241 | T23: =AVERAGE(Table24[[#This Row],[CZ01]:[CZ16]]) -> 0.11453925 | U23: =MAX(Table24[[#This Row],[CZ01]:[CZ16]]) -> 0.131436
B24: OfS | C24: =IFERROR( _xlfn.MINIFS( 'Combined Runs'!$P:$P, 'Combined Runs'!$K:$K, C$17, 'Combined Runs'!$J:$J, "*" & $B24 & "&0&cPVVE&New&Chiller__PumpCtrl*" ), "" ) -> 0.005402 | D24: =IFERROR( _xlfn.MINIFS( 'Combined Runs'!$P:$P, 'Combined Runs'!$K:$K, D$17, 'Combined Runs'!$J:$J, "*" & $B24 & "&0&cPVVE&New&Chiller__PumpCtrl*" ), "" ) -> 0.006918 | E24: =IFERROR( _xlfn.MINIFS( 'Combined Runs'!$P:$P, 'Combined Runs'!$K:$K, E$17, 'Combined Runs'!$J:$J, "*" & $B24 & "&0&cPVVE&New&Chiller__PumpCtrl*" ), "" ) -> 0.00679 | F24: =IFERROR( _xlfn.MINIFS( 'Combined Runs'!$P:$P, 'Combined Runs'!$K:$K, F$17, 'Combined Runs'!$J:$J, "*" & $B24 & "&0&cPVVE&New&Chiller__PumpCtrl*" ), "" ) -> 0.007043 | G24: =IFERROR( _xlfn.MINIFS( 'Combined Runs'!$P:$P, 'Combined Runs'!$K:$K, G$17, 'Combined Runs'!$J:$J, "*" & $B24 & "&0&cPVVE&New&Chiller__PumpCtrl*" ), "" ) -> 0.006297 | H24: =IFERROR( _xlfn.MINIFS( 'Combined Runs'!$P:$P, 'Combined Runs'!$K:$K, H$17, 'Combined Runs'!$J:$J, "*" & $B24 & "&0&cPVVE&New&Chiller__PumpCtrl*" ), "" ) -> 0.006807 | I24: =IFERROR( _xlfn.MINIFS( 'Combined Runs'!$P:$P, 'Combined Runs'!$K:$K, I$17, 'Combined Runs'!$J:$J, "*" & $B24 & "&0&cPVVE&New&Chiller__PumpCtrl*" ), "" ) -> 0.006956 | J24: =IFERROR( _xlfn.MINIFS( 'Combined Runs'!$P:$P, 'Combined Runs'!$K:$K, J$17, 'Combined Runs'!$J:$J, "*" & $B24 & "&0&cPVVE&New&Chiller__PumpCtrl*" ), "" ) -> 0.00744 | ... R24: =IFERROR( _xlfn.MINIFS( 'Combined Runs'!$P:$P, 'Combined Runs'!$K:$K, R$17, 'Combined Runs'!$J:$J, "*" & $B24 & "&0&cPVVE&New&Chiller__PumpCtrl*" ), "" ) -> 0.007276 | S24: =MIN(Table24[[#This Row],[CZ01]:[CZ16]]) -> 0.005402 | T24: =AVERAGE(Table24[[#This Row],[CZ01]:[CZ16]]) -> 0.0071648125 | U24: =MAX(Table24[[#This Row],[CZ01]:[CZ16]]) -> 0.008257
B25: Rt3 | C25: =IFERROR( _xlfn.MINIFS( 'Combined Runs'!$P:$P, 'Combined Runs'!$K:$K, C$17, 'Combined Runs'!$J:$J, "*" & $B25 & "&0&cPVVE&New&Chiller__PumpCtrl*" ), "" ) -> 0.065633 | D25: =IFERROR( _xlfn.MINIFS( 'Combined Runs'!$P:$P, 'Combined Runs'!$K:$K, D$17, 'Combined Runs'!$J:$J, "*" & $B25 & "&0&cPVVE&New&Chiller__PumpCtrl*" ), "" ) -> 0.115625 | E25: =IFERROR( _xlfn.MINIFS( 'Combined Runs'!$P:$P, 'Combined Runs'!$K:$K, E$17, 'Combined Runs'!$J:$J, "*" & $B25 & "&0&cPVVE&New&Chiller__PumpCtrl*" ), "" ) -> 0.107451 | F25: =IFERROR( _xlfn.MINIFS( 'Combined Runs'!$P:$P, 'Combined Runs'!$K:$K, F$17, 'Combined Runs'!$J:$J, "*" & $B25 & "&0&cPVVE&New&Chiller__PumpCtrl*" ), "" ) -> 0.118263 | G25: =IFERROR( _xlfn.MINIFS( 'Combined Runs'!$P:$P, 'Combined Runs'!$K:$K, G$17, 'Combined Runs'!$J:$J, "*" & $B25 & "&0&cPVVE&New&Chiller__PumpCtrl*" ), "" ) -> 0.100819 | H25: =IFERROR( _xlfn.MINIFS( 'Combined Runs'!$P:$P, 'Combined Runs'!$K:$K, H$17, 'Combined Runs'!$J:$J, "*" & $B25 & "&0&cPVVE&New&Chiller__PumpCtrl*" ), "" ) -> 0.109175 | I25: =IFERROR( _xlfn.MINIFS( 'Combined Runs'!$P:$P, 'Combined Runs'!$K:$K, I$17, 'Combined Runs'!$J:$J, "*" & $B25 & "&0&cPVVE&New&Chiller__PumpCtrl*" ), "" ) -> 0.111805 | J25: =IFERROR( _xlfn.MINIFS( 'Combined Runs'!$P:$P, 'Combined Runs'!$K:$K, J$17, 'Combined Runs'!$J:$J, "*" & $B25 & "&0&cPVVE&New&Chiller__PumpCtrl*" ), "" ) -> 0.122185 | ... R25: =IFERROR( _xlfn.MINIFS( 'Combined Runs'!$P:$P, 'Combined Runs'!$K:$K, R$17, 'Combined Runs'!$J:$J, "*" & $B25 & "&0&cPVVE&New&Chiller__PumpCtrl*" ), "" ) -> 0.083229 | S25: =MIN(Table24[[#This Row],[CZ01]:[CZ16]]) -> 0.065633 | T25: =AVERAGE(Table24[[#This Row],[CZ01]:[CZ16]]) -> 0.105595 | U25: =MAX(Table24[[#This Row],[CZ01]:[CZ16]]) -> 0.132571
B26: Htl | C26: =IFERROR( _xlfn.MINIFS( 'Combined Runs'!$P:$P, 'Combined Runs'!$K:$K, C$17, 'Combined Runs'!$J:$J, "*" & $B26 & "&0&cPVVE&New&Chiller__PumpCtrl*" ), "" ) -> 0.015125 | D26: =IFERROR( _xlfn.MINIFS( 'Combined Runs'!$P:$P, 'Combined Runs'!$K:$K, D$17, 'Combined Runs'!$J:$J, "*" & $B26 & "&0&cPVVE&New&Chiller__PumpCtrl*" ), "" ) -> 0.019748 | E26: =IFERROR( _xlfn.MINIFS( 'Combined Runs'!$P:$P, 'Combined Runs'!$K:$K, E$17, 'Combined Runs'!$J:$J, "*" & $B26 & "&0&cPVVE&New&Chiller__PumpCtrl*" ), "" ) -> 0.018618 | F26: =IFERROR( _xlfn.MINIFS( 'Combined Runs'!$P:$P, 'Combined Runs'!$K:$K, F$17, 'Combined Runs'!$J:$J, "*" & $B26 & "&0&cPVVE&New&Chiller__PumpCtrl*" ), "" ) -> 0.020021 | G26: =IFERROR( _xlfn.MINIFS( 'Combined Runs'!$P:$P, 'Combined Runs'!$K:$K, G$17, 'Combined Runs'!$J:$J, "*" & $B26 & "&0&cPVVE&New&Chiller__PumpCtrl*" ), "" ) -> 0.017273 | H26: =IFERROR( _xlfn.MINIFS( 'Combined Runs'!$P:$P, 'Combined Runs'!$K:$K, H$17, 'Combined Runs'!$J:$J, "*" & $B26 & "&0&cPVVE&New&Chiller__PumpCtrl*" ), "" ) -> 0.018309 | I26: =IFERROR( _xlfn.MINIFS( 'Combined Runs'!$P:$P, 'Combined Runs'!$K:$K, I$17, 'Combined Runs'!$J:$J, "*" & $B26 & "&0&cPVVE&New&Chiller__PumpCtrl*" ), "" ) -> 0.01924 | J26: =IFERROR( _xlfn.MINIFS( 'Combined Runs'!$P:$P, 'Combined Runs'!$K:$K, J$17, 'Combined Runs'!$J:$J, "*" & $B26 & "&0&cPVVE&New&Chiller__PumpCtrl*" ), "" ) -> 0.020363 | ... R26: =IFERROR( _xlfn.MINIFS( 'Combined Runs'!$P:$P, 'Combined Runs'!$K:$K, R$17, 'Combined Runs'!$J:$J, "*" & $B26 & "&0&cPVVE&New&Chiller__PumpCtrl*" ), "" ) -> 0.020212 | S26: =MIN(Table24[[#This Row],[CZ01]:[CZ16]]) -> 0.015125 | T26: =AVERAGE(Table24[[#This Row],[CZ01]:[CZ16]]) -> 0.02056675 | U26: =MAX(Table24[[#This Row],[CZ01]:[CZ16]]) -> 0.024418

Sheet Min flow rate
A1: Tech ID | B1: NE-Chiller-PumpCtrl-Full-Std
B2: Min Flow Rate
B3: Existing Building | S3: Minimum CW Pump Flow Rate (constant) (m3/s)
B4: Building Type | C4: CZ01 | D4: CZ02 | E4: CZ03 | F4: CZ04 | G4: CZ05 | H4: CZ06 | I4: CZ07 | J4: CZ08 | K4: CZ09 | L4: CZ10 | M4: CZ11 | N4: CZ12 | O4: CZ13 | P4: CZ14 | Q4: CZ15 | R4: CZ16 | S4: Min Across All CZ | T4: Average Across All CZ2 | U4: Max Across All CZ3 | W4: Water density
B5: ECC | C5: ='Design flow rate'!C5*0.7 -> 0.0979874 | D5: ='Design flow rate'!D5*0.7 -> 0.1259951 | E5: ='Design flow rate'!E5*0.7 -> 0.1184218 | F5: ='Design flow rate'!F5*0.7 -> 0.1275764 | G5: ='Design flow rate'!G5*0.7 -> 0.1119335 | H5: ='Design flow rate'!H5*0.7 -> 0.1167103 | I5: ='Design flow rate'!I5*0.7 -> 0.1196916 | J5: ='Design flow rate'!J5*0.7 -> 0.1284731 | ... U5: ='Design flow rate'!U5*0.7 -> 0.1468705 | W5: 995 | X5: kg/m3
B6: Ese | C6: ='Design flow rate'!C6*0.7 -> 0.0162645 | D6: ='Design flow rate'!D6*0.7 -> 0.0208859 | E6: ='Design flow rate'!E6*0.7 -> 0.0198128 | F6: ='Design flow rate'!F6*0.7 -> 0.0212093 | G6: ='Design flow rate'!G6*0.7 -> 0.0186536 | H6: ='Design flow rate'!H6*0.7 -> 0.0195237 | I6: ='Design flow rate'!I6*0.7 -> 0.0200067 | J6: ='Design flow rate'!J6*0.7 -> 0.021392 | ... U6: ='Design flow rate'!U6*0.7 -> 0.0238126
B7: Eun | C7: ='Design flow rate'!C7*0.7 -> 0.2507876 | D7: ='Design flow rate'!D7*0.7 -> 0.2974377 | E7: ='Design flow rate'!E7*0.7 -> 0.2877217 | F7: ='Design flow rate'!F7*0.7 -> 0.3002139 | G7: ='Design flow rate'!G7*0.7 -> 0.273154 | H7: ='Design flow rate'!H7*0.7 -> 0.2816226 | I7: ='Design flow rate'!I7*0.7 -> 0.2868005 | J7: ='Design flow rate'!J7*0.7 -> 0.3022432 | ... U7: ='Design flow rate'!U7*0.7 -> 0.3297091
B8: Hsp | C8: ='Design flow rate'!C8*0.7 -> 0.1175783 | D8: ='Design flow rate'!D8*0.7 -> 0.1446697 | E8: ='Design flow rate'!E8*0.7 -> 0.1375934 | F8: ='Design flow rate'!F8*0.7 -> 0.1465933 | G8: ='Design flow rate'!G8*0.7 -> 0.1326878 | H8: ='Design flow rate'!H8*0.7 -> 0.1380764 | I8: ='Design flow rate'!I8*0.7 -> 0.1414966 | J8: ='Design flow rate'!J8*0.7 -> 0.1486912 | ... U8: ='Design flow rate'!U8*0.7 -> 0.1652805
B9: Nrs | C9: ='Design flow rate'!C9*0.7 -> 0.0149891 | D9: ='Design flow rate'!D9*0.7 -> 0.0190638 | E9: ='Design flow rate'!E9*0.7 -> 0.0180397 | F9: ='Design flow rate'!F9*0.7 -> 0.0193137 | G9: ='Design flow rate'!G9*0.7 -> 0.0169568 | H9: ='Design flow rate'!H9*0.7 -> 0.0176778 | I9: ='Design flow rate'!I9*0.7 -> 0.0180089 | J9: ='Design flow rate'!J9*0.7 -> 0.0193781 | ... U9: ='Design flow rate'!U9*0.7 -> 0.0219464
B10: OfL | C10: ='Design flow rate'!C10*0.7 -> 0.096964 | D10: ='Design flow rate'!D10*0.7 -> 0.1208242 | E10: ='Design flow rate'!E10*0.7 -> 0.1142127 | F10: ='Design flow rate'!F10*0.7 -> 0.1216446 | G10: ='Design flow rate'!G10*0.7 -> 0.1103949 | H10: ='Design flow rate'!H10*0.7 -> 0.111706 | I10: ='Design flow rate'!I10*0.7 -> 0.112427 | J10: ='Design flow rate'!J10*0.7 -> 0.1209565 | ... U10: ='Design flow rate'!U10*0.7 -> 0.1329524
B11: OfS | C11: ='Design flow rate'!C11*0.7 -> 0.0072856 | D11: ='Design flow rate'!D11*0.7 -> 0.009072 | E11: ='Design flow rate'!E11*0.7 -> 0.0087143 | F11: ='Design flow rate'!F11*0.7 -> 0.0091903 | G11: ='Design flow rate'!G11*0.7 -> 0.0083076 | H11: ='Design flow rate'!H11*0.7 -> 0.0084889 | I11: ='Design flow rate'!I11*0.7 -> 0.0084945 | J11: ='Design flow rate'!J11*0.7 -> 0.0091532 | ... U11: ='Design flow rate'!U11*0.7 -> 0.0099099
B12: Rt3 | C12: ='Design flow rate'!C12*0.7 -> 0.0643265 | D12: ='Design flow rate'!D12*0.7 -> 0.0855477 | E12: ='Design flow rate'!E12*0.7 -> 0.0809067 | F12: ='Design flow rate'!F12*0.7 -> 0.087633 | G12: ='Design flow rate'!G12*0.7 -> 0.0769657 | H12: ='Design flow rate'!H12*0.7 -> 0.0822451 | I12: ='Design flow rate'!I12*0.7 -> 0.0859327 | J12: ='Design flow rate'!J12*0.7 -> 0.0899339 | ... U12: ='Design flow rate'!U12*0.7 -> 0.1011465
B13: Htl | C13: ='Design flow rate'!C13*0.7 -> 0.0120043 | D13: ='Design flow rate'!D13*0.7 -> 0.0160405 | E13: ='Design flow rate'!E13*0.7 -> 0.0151018 | F13: ='Design flow rate'!F13*0.7 -> 0.0162645 | G13: ='Design flow rate'!G13*0.7 -> 0.013923 | H13: ='Design flow rate'!H13*0.7 -> 0.0146881 | I13: ='Design flow rate'!I13*0.7 -> 0.0149786 | J13: ='Design flow rate'!J13*0.7 -> 0.0164332 | ... U13: ='Design flow rate'!U13*0.7 -> 0.0192682
B16: New Building | S16: Minimum CW Pump Flow Rate (constant) (m3/s)
B17: Building Type | C17: CZ01 | D17: CZ02 | E17: CZ03 | F17: CZ04 | G17: CZ05 | H17: CZ06 | I17: CZ07 | J17: CZ08 | K17: CZ09 | L17: CZ10 | M17: CZ11 | N17: CZ12 | O17: CZ13 | P17: CZ14 | Q17: CZ15 | R17: CZ16 | S17: Min Across All CZ | T17: Average Across All CZ2 | U17: Max Across All CZ3
B18: ECC | C18: ='Design flow rate'!C18*0.7 -> 0.075866 | D18: ='Design flow rate'!D18*0.7 -> 0.1056958 | E18: ='Design flow rate'!E18*0.7 -> 0.0980777 | F18: ='Design flow rate'!F18*0.7 -> 0.1071798 | G18: ='Design flow rate'!G18*0.7 -> 0.0916041 | H18: ='Design flow rate'!H18*0.7 -> 0.0971845 | I18: ='Design flow rate'!I18*0.7 -> 0.0999453 | J18: ='Design flow rate'!J18*0.7 -> 0.1088304 | ... U18: ='Design flow rate'!U18*0.7 -> 0.1204651
B19: Ese | C19: ='Design flow rate'!C19*0.7 -> 0.0115388 | D19: ='Design flow rate'!D19*0.7 -> 0.016597 | E19: ='Design flow rate'!E19*0.7 -> 0.0155274 | F19: ='Design flow rate'!F19*0.7 -> 0.0168826 | G19: ='Design flow rate'!G19*0.7 -> 0.0143612 | H19: ='Design flow rate'!H19*0.7 -> 0.0155225 | I19: ='Design flow rate'!I19*0.7 -> 0.0159705 | J19: ='Design flow rate'!J19*0.7 -> 0.0173376 | ... U19: ='Design flow rate'!U19*0.7 -> 0.018886
B20: Eun | C20: ='Design flow rate'!C20*0.7 -> 0.1782802 | D20: ='Design flow rate'!D20*0.7 -> 0.2142196 | E20: ='Design flow rate'!E20*0.7 -> 0.2075619 | F20: ='Design flow rate'!F20*0.7 -> 0.2165457 | G20: ='Design flow rate'!G20*0.7 -> 0.1927821 | H20: ='Design flow rate'!H20*0.7 -> 0.202468 | I20: ='Design flow rate'!I20*0.7 -> 0.2092433 | J20: ='Design flow rate'!J20*0.7 -> 0.2186219 | ... U20: ='Design flow rate'!U20*0.7 -> 0.2467703
B21: Hsp | C21: ='Design flow rate'!C21*0.7 -> 0.1000762 | D21: ='Design flow rate'!D21*0.7 -> 0.1346667 | E21: ='Design flow rate'!E21*0.7 -> 0.1266209 | F21: ='Design flow rate'!F21*0.7 -> 0.1362914 | G21: ='Design flow rate'!G21*0.7 -> 0.1211063 | H21: ='Design flow rate'!H21*0.7 -> 0.1271291 | I21: ='Design flow rate'!I21*0.7 -> 0.1293971 | J21: ='Design flow rate'!J21*0.7 -> 0.1386154 | ... U21: ='Design flow rate'!U21*0.7 -> 0.1498749
B22: Nrs | C22: ='Design flow rate'!C22*0.7 -> 0.0107156 | D22: ='Design flow rate'!D22*0.7 -> 0.01379 | E22: ='Design flow rate'!E22*0.7 -> 0.0133252 | F22: ='Design flow rate'!F22*0.7 -> 0.0140203 | G22: ='Design flow rate'!G22*0.7 -> 0.0123417 | H22: ='Design flow rate'!H22*0.7 -> 0.0131831 | I22: ='Design flow rate'!I22*0.7 -> 0.0136227 | J22: ='Design flow rate'!J22*0.7 -> 0.0145705 | ... U22: ='Design flow rate'!U22*0.7 -> 0.0165725
B23: OfL | C23: ='Design flow rate'!C23*0.7 -> 0.0631687 | D23: ='Design flow rate'!D23*0.7 -> 0.0788424 | E23: ='Design flow rate'!E23*0.7 -> 0.0747817 | F23: ='Design flow rate'!F23*0.7 -> 0.0792834 | G23: ='Design flow rate'!G23*0.7 -> 0.0708736 | H23: ='Design flow rate'!H23*0.7 -> 0.0734041 | I23: ='Design flow rate'!I23*0.7 -> 0.0750162 | J23: ='Design flow rate'!J23*0.7 -> 0.0796922 | ... U23: ='Design flow rate'!U23*0.7 -> 0.0920052
B24: OfS | C24: ='Design flow rate'!C24*0.7 -> 0.0037814 | D24: ='Design flow rate'!D24*0.7 -> 0.0048426 | E24: ='Design flow rate'!E24*0.7 -> 0.004753 | F24: ='Design flow rate'!F24*0.7 -> 0.0049301 | G24: ='Design flow rate'!G24*0.7 -> 0.0044079 | H24: ='Design flow rate'!H24*0.7 -> 0.0047649 | I24: ='Design flow rate'!I24*0.7 -> 0.0048692 | J24: ='Design flow rate'!J24*0.7 -> 0.005208 | ... U24: ='Design flow rate'!U24*0.7 -> 0.0057799
B25: Rt3 | C25: ='Design flow rate'!C25*0.7 -> 0.0459431 | D25: ='Design flow rate'!D25*0.7 -> 0.0809375 | E25: ='Design flow rate'!E25*0.7 -> 0.0752157 | F25: ='Design flow rate'!F25*0.7 -> 0.0827841 | G25: ='Design flow rate'!G25*0.7 -> 0.0705733 | H25: ='Design flow rate'!H25*0.7 -> 0.0764225 | I25: ='Design flow rate'!I25*0.7 -> 0.0782635 | J25: ='Design flow rate'!J25*0.7 -> 0.0855295 | ... U25: ='Design flow rate'!U25*0.7 -> 0.0927997
B26: Htl | C26: ='Design flow rate'!C26*0.7 -> 0.0105875 | D26: ='Design flow rate'!D26*0.7 -> 0.0138236 | E26: ='Design flow rate'!E26*0.7 -> 0.0130326 | F26: ='Design flow rate'!F26*0.7 -> 0.0140147 | G26: ='Design flow rate'!G26*0.7 -> 0.0120911 | H26: ='Design flow rate'!H26*0.7 -> 0.0128163 | I26: ='Design flow rate'!I26*0.7 -> 0.013468 | J26: ='Design flow rate'!J26*0.7 -> 0.0142541 | ... U26: ='Design flow rate'!U26*0.7 -> 0.0170926
B28: Minimum CW Pump Flow Rate (constant) (kg/s)
B29: Existing (kg/s)
B30: ECC | C30: =C5*$W$5 -> 97.497463 | D30: =D5*$W$5 -> 125.36512 | E30: =E5*$W$5 -> 117.82969 | F30: =F5*$W$5 -> 126.93852 | G30: =G5*$W$5 -> 111.37383 | H30: =H5*$W$5 -> 116.12675 | I30: =I5*$W$5 -> 119.09314 | J30: =J5*$W$5 -> 127.83073 | ... R30: =R5*$W$5 -> 123.95053
B31: Ese | C31: =C6*$W$5 -> 16.183177 | D31: =D6*$W$5 -> 20.78147 | E31: =E6*$W$5 -> 19.713736 | F31: =F6*$W$5 -> 21.103253 | G31: =G6*$W$5 -> 18.560332 | H31: =H6*$W$5 -> 19.426081 | I31: =I6*$W$5 -> 19.906667 | J31: =J6*$W$5 -> 21.28504 | ... R31: =R6*$W$5 -> 20.074523
B32: Eun | C32: =C7*$W$5 -> 249.53366 | D32: =D7*$W$5 -> 295.95051 | E32: =E7*$W$5 -> 286.28309 | F32: =F7*$W$5 -> 298.71283 | G32: =G7*$W$5 -> 271.78823 | H32: =H7*$W$5 -> 280.21449 | I32: =I7*$W$5 -> 285.3665 | J32: =J7*$W$5 -> 300.73198 | ... R32: =R7*$W$5 -> 290.99004
B33: Hsp | C33: =C8*$W$5 -> 116.99041 | D33: =D8*$W$5 -> 143.94635 | E33: =E8*$W$5 -> 136.90543 | F33: =F8*$W$5 -> 145.86033 | G33: =G8*$W$5 -> 132.02436 | H33: =H8*$W$5 -> 137.38602 | I33: =I8*$W$5 -> 140.78912 | J33: =J8*$W$5 -> 147.94774 | ... R33: =R8*$W$5 -> 144.34893
B34: Nrs | C34: =C9*$W$5 -> 14.914155 | D34: =D9*$W$5 -> 18.968481 | E34: =E9*$W$5 -> 17.949502 | F34: =F9*$W$5 -> 19.217132 | G34: =G9*$W$5 -> 16.872016 | H34: =H9*$W$5 -> 17.589411 | I34: =I9*$W$5 -> 17.918855 | J34: =J9*$W$5 -> 19.281209 | ... R34: =R9*$W$5 -> 18.691274
B35: OfL | C35: =C10*$W$5 -> 96.47918 | D35: =D10*$W$5 -> 120.22008 | E35: =E10*$W$5 -> 113.64164 | F35: =F10*$W$5 -> 121.03638 | G35: =G10*$W$5 -> 109.84293 | H35: =H10*$W$5 -> 111.14747 | I35: =I10*$W$5 -> 111.86486 | J35: =J10*$W$5 -> 120.35172 | ... R35: =R10*$W$5 -> 120.68255
B36: OfS | C36: =C11*$W$5 -> 7.249172 | D36: =D11*$W$5 -> 9.02664 | E36: =E11*$W$5 -> 8.6707285 | F36: =F11*$W$5 -> 9.1443485 | G36: =G11*$W$5 -> 8.266062 | H36: =H11*$W$5 -> 8.4464555 | I36: =I11*$W$5 -> 8.4520275 | J36: =J11*$W$5 -> 9.107434 | ... R36: =R11*$W$5 -> 9.034998
B37: Rt3 | C37: =C12*$W$5 -> 64.004867 | D37: =D12*$W$5 -> 85.119961 | E37: =E12*$W$5 -> 80.502167 | F37: =F12*$W$5 -> 87.194835 | G37: =G12*$W$5 -> 76.580871 | H37: =H12*$W$5 -> 81.833875 | I37: =I12*$W$5 -> 85.503036 | J37: =J12*$W$5 -> 89.48423 | ... R37: =R12*$W$5 -> 81.946011
B38: Htl | C38: =C13*$W$5 -> 11.944279 | D38: =D13*$W$5 -> 15.960297 | E38: =E13*$W$5 -> 15.026291 | F38: =F13*$W$5 -> 16.183177 | G38: =G13*$W$5 -> 13.853385 | H38: =H13*$W$5 -> 14.61466 | I38: =I13*$W$5 -> 14.903707 | J38: =J13*$W$5 -> 16.351034 | ... R38: =R13*$W$5 -> 16.156014
B41: CW Design Flow Rate (constant) (kg/s)
B42: New (kg/s)
B43: ECC | C43: =C18*$W$5 -> 75.48667 | D43: =D18*$W$5 -> 105.16732 | E43: =E18*$W$5 -> 97.587311 | F43: =F18*$W$5 -> 106.6439 | G43: =G18*$W$5 -> 91.146079 | H43: =H18*$W$5 -> 96.698577 | I43: =I18*$W$5 -> 99.445573 | J43: =J18*$W$5 -> 108.28625 | ... R43: =R18*$W$5 -> 98.085309
B44: Ese | C44: =C19*$W$5 -> 11.481106 | D44: =D19*$W$5 -> 16.514015 | E44: =E19*$W$5 -> 15.449763 | F44: =F19*$W$5 -> 16.798187 | G44: =G19*$W$5 -> 14.289394 | H44: =H19*$W$5 -> 15.444888 | I44: =I19*$W$5 -> 15.890647 | J44: =J19*$W$5 -> 17.250912 | ... R44: =R19*$W$5 -> 14.331881
B45: Eun | C45: =C20*$W$5 -> 177.3888 | D45: =D20*$W$5 -> 213.1485 | E45: =E20*$W$5 -> 206.52409 | F45: =F20*$W$5 -> 215.46297 | G45: =G20*$W$5 -> 191.81819 | H45: =H20*$W$5 -> 201.45566 | I45: =I20*$W$5 -> 208.19708 | J45: =J20*$W$5 -> 217.52879 | ... R45: =R20*$W$5 -> 207.88993
...

Sheet Combined Runs
B2: Paste into codes files or pump_min_flow.csv | F2: Calc inputs
F3: Min flow fraction | G3: 0.7
D4: Minimum CW Pump Flow Rate (constant) (kg/s) | F4: Water density | G4: 995 | H4: kg/m3
B6: cohort_name | C6: climate_name | D6: :cw_pump_min_flow_rate | E6: Intermediate/review -> | F6: TechID | G6: CW Design Flow Rate (constant) (m3/s) | H6: CW Design Flow Rate (constant) (kg/s) | I6: Simulation data -> | J6: File Name | K6: BldgLoc | L6: CHW Pump Power (Constant) | M6: CW Pump Power (Constant) | N6: CHW Pump Power (Variable) | O6: CW Pump Power (Variable) | P6: CW Design Flow Rate (constant) (m3/s) | Q6: Electricity/Heating | R6: Electricity/Cooling | S6: Electricity/Interior Lighting | T6: Electricity/Exterior Lighting | U6: Electricity/Interior Equipment | V6: Electricity/Exterior Equipment | W6: Electricity/Fans | X6: Electricity/Pumps | Y6: Electricity/Heat Rejection | Z6: Electricity/Humidification | AA6: Electricity/Heat Recovery | AB6: Electricity/Water Systems | AC6: Electricity/Refrigeration | AD6: Electricity/Generators | AE6: Natural Gas/Heating | AF6: Natural Gas/Cooling | AG6: Natural Gas/Interior Lighting | AH6: Natural Gas/Exterior Lighting | AI6: Natural Gas/Interior Equipment | AJ6: Natural Gas/Exterior Equipment | AK6: Natural Gas/Fans | AL6: Natural Gas/Pumps | AM6: Natural Gas/Heat Rejection | AN6: Natural Gas/Humidification | AO6: Natural Gas/Heat Recovery | AP6: Natural Gas/Water Systems | AQ6: Natural Gas/Refrigeration | AR6: Natural Gas/Generators | AS6: Electricity:Facility [J](Hourly)
B7: {=INDEX(_xlfn.TEXTSPLIT($J7,"/"),3)} -> ECC&0&cPVVE&Ex&Chiller__PumpCtrl | C7: {=INDEX(_xlfn.TEXTSPLIT($J7,"/"),2)} -> CZ01 | D7: =$G$3*H7 -> 97.497463 | F7: {=INDEX(_xlfn.TEXTSPLIT($J7,"/"),4)} -> NE-Chiller-CHWPumpCtrl-Full-Msr | G7: =$P7 -> 0.139982 | H7: =$G$4*G7 -> 139.28209 | J7: runs/CZ01/ECC&0&cPVVE&Ex&Chiller__PumpCtrl/NE-Chiller-CHWPumpCtrl-Full-Msr/instance-out.sql | K7: CZ01 | M7: 26820.85 | N7: 9394.92 | P7: 0.139982 | Q7: 0 | R7: 88910.01 | S7: 350734.07 | T7: 0 | U7: 936314.72 | V7: 0 | W7: 249804.28 | X7: 177154.51 | Y7: 198095.83 | Z7: 0 | AA7: 0 | AB7: 0 | AC7: 0 | AD7: 0 | AE7: 333355.5 | AF7: 0 | AG7: 0 | AH7: 0 | AI7: 68627.6 | AJ7: 0 | AK7: 0 | AL7: 0 | AM7: 0 | AN7: 0 | AO7: 0 | AP7: 530229.18 | AQ7: 0 | AR7: 0 | AS7: 1.4309967e+09
B8: {=INDEX(_xlfn.TEXTSPLIT($J8,"/"),3)} -> ECC&0&cPVVE&Ex&Chiller__PumpCtrl | C8: {=INDEX(_xlfn.TEXTSPLIT($J8,"/"),2)} -> CZ02 | D8: =$G$3*H8 -> 125.36512 | F8: {=INDEX(_xlfn.TEXTSPLIT($J8,"/"),4)} -> NE-Chiller-CHWPumpCtrl-Full-Msr | G8: =$P8 -> 0.179993 | H8: =$G$4*G8 -> 179.09303 | J8: runs/CZ02/ECC&0&cPVVE&Ex&Chiller__PumpCtrl/NE-Chiller-CHWPumpCtrl-Full-Msr/instance-out.sql | K8: CZ02 | M8: 34487.19 | N8: 12080.31 | P8: 0.179993 | Q8: 0 | R8: 630186.25 | S8: 350734.07 | T8: 0 | U8: 936314.72 | V8: 0 | W8: 344486.25 | X8: 246662.33 | Y8: 250262.28 | Z8: 0 | AA8: 0 | AB8: 0 | AC8: 0 | AD8: 0 | AE8: 450287.69 | AF8: 0 | AG8: 0 | AH8: 0 | AI8: 68627.6 | AJ8: 0 | AK8: 0 | AL8: 0 | AM8: 0 | AN8: 0 | AO8: 0 | AP8: 486328.32 | AQ8: 0 | AR8: 0 | AS8: 2.5355726e+09
B9: {=INDEX(_xlfn.TEXTSPLIT($J9,"/"),3)} -> ECC&0&cPVVE&Ex&Chiller__PumpCtrl | C9: {=INDEX(_xlfn.TEXTSPLIT($J9,"/"),2)} -> CZ03 | D9: =$G$3*H9 -> 117.82969 | F9: {=INDEX(_xlfn.TEXTSPLIT($J9,"/"),4)} -> NE-Chiller-CHWPumpCtrl-Full-Msr | G9: =$P9 -> 0.169174 | H9: =$G$4*G9 -> 168.32813 | J9: runs/CZ03/ECC&0&cPVVE&Ex&Chiller__PumpCtrl/NE-Chiller-CHWPumpCtrl-Full-Msr/instance-out.sql | K9: CZ03 | M9: 32414.14 | N9: 11354.16 | P9: 0.169174 | Q9: 0 | R9: 423117.69 | S9: 350734.07 | T9: 0 | U9: 936314.72 | V9: 0 | W9: 256074.19 | X9: 243577.38 | Y9: 263610.52 | Z9: 0 | AA9: 0 | AB9: 0 | AC9: 0 | AD9: 0 | AE9: 171303.16 | AF9: 0 | AG9: 0 | AH9: 0 | AI9: 68627.6 | AJ9: 0 | AK9: 0 | AL9: 0 | AM9: 0 | AN9: 0 | AO9: 0 | AP9: 484908.14 | AQ9: 0 | AR9: 0 | AS9: 1.9133769e+09
B10: {=INDEX(_xlfn.TEXTSPLIT($J10,"/"),3)} -> ECC&0&cPVVE&Ex&Chiller__PumpCtrl | C10: {=INDEX(_xlfn.TEXTSPLIT($J10,"/"),2)} -> CZ04 | D10: =$G$3*H10 -> 126.93852 | F10: {=INDEX(_xlfn.TEXTSPLIT($J10,"/"),4)} -> NE-Chiller-CHWPumpCtrl-Full-Msr | G10: =$P10 -> 0.182252 | H10: =$G$4*G10 -> 181.34074 | J10: runs/CZ04/ECC&0&cPVVE&Ex&Chiller__PumpCtrl/NE-Chiller-CHWPumpCtrl-Full-Msr/instance-out.sql | K10: CZ04 | M10: 34919.87 | N10: 12231.88 | P10: 0.182252 | Q10: 0 | R10: 655938.59 | S10: 350734.07 | T10: 0 | U10: 936314.72 | V10: 0 | W10: 302679.32 | X10: 265529.52 | Y10: 286420.26 | Z10: 0 | AA10: 0 | AB10: 0 | AC10: 0 | AD10: 0 | AE10: 239728.99 | AF10: 0 | AG10: 0 | AH10: 0 | AI10: 68627.6 | AJ10: 0 | AK10: 0 | AL10: 0 | AM10: 0 | AN10: 0 | AO10: 0 | AP10: 467639.01 | AQ10: 0 | AR10: 0 | AS10: 2.3417931e+09
B11: {=INDEX(_xlfn.TEXTSPLIT($J11,"/"),3)} -> ECC&0&cPVVE&Ex&Chiller__PumpCtrl | C11: {=INDEX(_xlfn.TEXTSPLIT($J11,"/"),2)} -> CZ05 | D11: =$G$3*H11 -> 111.37383 | F11: {=INDEX(_xlfn.TEXTSPLIT($J11,"/"),4)} -> NE-Chiller-CHWPumpCtrl-Full-Msr | G11: =$P11 -> 0.159905 | H11: =$G$4*G11 -> 159.10547 | J11: runs/CZ05/ECC&0&cPVVE&Ex&Chiller__PumpCtrl/NE-Chiller-CHWPumpCtrl-Full-Msr/instance-out.sql | K11: CZ05 | M11: 30638.23 | N11: 10732.08 | P11: 0.159905 | Q11: 0 | R11: 487292.09 | S11: 350734.07 | T11: 0 | U11: 936314.72 | V11: 0 | W11: 265387.39 | X11: 235024.77 | Y11: 249889.62 | Z11: 0 | AA11: 0 | AB11: 0 | AC11: 0 | AD11: 0 | AE11: 174062.07 | AF11: 0 | AG11: 0 | AH11: 0 | AI11: 68627.6 | AJ11: 0 | AK11: 0 | AL11: 0 | AM11: 0 | AN11: 0 | AO11: 0 | AP11: 485029.65 | AQ11: 0 | AR11: 0 | AS11: 1.2799539e+09
B12: {=INDEX(_xlfn.TEXTSPLIT($J12,"/"),3)} -> ECC&0&cPVVE&Ex&Chiller__PumpCtrl | C12: {=INDEX(_xlfn.TEXTSPLIT($J12,"/"),2)} -> CZ06 | D12: =$G$3*H12 -> 116.12675 | F12: {=INDEX(_xlfn.TEXTSPLIT($J12,"/"),4)} -> NE-Chiller-CHWPumpCtrl-Full-Msr | G12: =$P12 -> 0.166729 | H12: =$G$4*G12 -> 165.89535 | J12: runs/CZ06/ECC&0&cPVVE&Ex&Chiller__PumpCtrl/NE-Chiller-CHWPumpCtrl-Full-Msr/instance-out.sql | K12: CZ06 | M12: 31945.7 | N12: 11190.07 | P12: 0.166729 | Q12: 0 | R12: 878658.01 | S12: 350734.07 | T12: 0 | U12: 936314.72 | V12: 0 | W12: 303296.08 | X12: 273088.55 | Y12: 294907.97 | Z12: 0 | AA12: 0 | AB12: 0 | AC12: 0 | AD12: 0 | AE12: 102125.54 | AF12: 0 | AG12: 0 | AH12: 0 | AI12: 68627.6 | AJ12: 0 | AK12: 0 | AL12: 0 | AM12: 0 | AN12: 0 | AO12: 0 | AP12: 446563.07 | AQ12: 0 | AR12: 0 | AS12: 1.2734191e+09
B13: {=INDEX(_xlfn.TEXTSPLIT($J13,"/"),3)} -> ECC&0&cPVVE&Ex&Chiller__PumpCtrl | C13: {=INDEX(_xlfn.TEXTSPLIT($J13,"/"),2)} -> CZ07 | D13: =$G$3*H13 -> 119.09314 | F13: {=INDEX(_xlfn.TEXTSPLIT($J13,"/"),4)} -> NE-Chiller-CHWPumpCtrl-Full-Msr | G13: =$P13 -> 0.170988 | H13: =$G$4*G13 -> 170.13306 | J13: runs/CZ07/ECC&0&cPVVE&Ex&Chiller__PumpCtrl/NE-Chiller-CHWPumpCtrl-Full-Msr/instance-out.sql | K13: CZ07 | M13: 32761.73 | N13: 11475.91 | P13: 0.170988 | Q13: 0 | R13: 952329.75 | S13: 350734.07 | T13: 0 | U13: 936314.72 | V13: 0 | W13: 325690.06 | X13: 280886.81 | Y13: 302120.61 | Z13: 0 | AA13: 0 | AB13: 0 | AC13: 0 | AD13: 0 | AE13: 166418.81 | AF13: 0 | AG13: 0 | AH13: 0 | AI13: 68627.6 | AJ13: 0 | AK13: 0 | AL13: 0 | AM13: 0 | AN13: 0 | AO13: 0 | AP13: 440567.05 | AQ13: 0 | AR13: 0 | AS13: 1.4700416e+09
B14: {=INDEX(_xlfn.TEXTSPLIT($J14,"/"),3)} -> ECC&0&cPVVE&Ex&Chiller__PumpCtrl | C14: {=INDEX(_xlfn.TEXTSPLIT($J14,"/"),2)} -> CZ08 | D14: =$G$3*H14 -> 127.83073 | F14: {=INDEX(_xlfn.TEXTSPLIT($J14,"/"),4)} -> NE-Chiller-CHWPumpCtrl-Full-Msr | G14: =$P14 -> 0.183533 | H14: =$G$4*G14 -> 182.61533 | J14: runs/CZ08/ECC&0&cPVVE&Ex&Chiller__PumpCtrl/NE-Chiller-CHWPumpCtrl-Full-Msr/instance-out.sql | K14: CZ08 | M14: 35165.43 | N14: 12317.89 | P14: 0.183533 | Q14: 0 | R14: 982157.24 | S14: 350734.07 | T14: 0 | U14: 936314.72 | V14: 0 | W14: 325090.01 | X14: 293306.18 | Y14: 315030.58 | Z14: 0 | AA14: 0 | AB14: 0 | AC14: 0 | AD14: 0 | AE14: 204240.78 | AF14: 0 | AG14: 0 | AH14: 0 | AI14: 68627.6 | AJ14: 0 | AK14: 0 | AL14: 0 | AM14: 0 | AN14: 0 | AO14: 0 | AP14: 439685.55 | AQ14: 0 | AR14: 0 | AS14: 1.4433895e+09
B15: {=INDEX(_xlfn.TEXTSPLIT($J15,"/"),3)} -> ECC&0&cPVVE&Ex&Chiller__PumpCtrl | C15: {=INDEX(_xlfn.TEXTSPLIT($J15,"/"),2)} -> CZ09 | D15: =$G$3*H15 -> 129.58661 | F15: {=INDEX(_xlfn.TEXTSPLIT($J15,"/"),4)} -> NE-Chiller-CHWPumpCtrl-Full-Msr | G15: =$P15 -> 0.186054 | H15: =$G$4*G15 -> 185.12373 | J15: runs/CZ09/ECC&0&cPVVE&Ex&Chiller__PumpCtrl/NE-Chiller-CHWPumpCtrl-Full-Msr/instance-out.sql | K15: CZ09 | M15: 35648.49 | N15: 12487.1 | P15: 0.186054 | Q15: 0 | R15: 1238916.1 | S15: 350734.07 | T15: 0 | U15: 936314.72 | V15: 0 | W15: 404672.05 | X15: 305357.28 | Y15: 324102.92 | Z15: 0 | AA15: 0 | AB15: 0 | AC15: 0 | AD15: 0 | AE15: 380325.41 | AF15: 0 | AG15: 0 | AH15: 0 | AI15: 68627.6 | AJ15: 0 | AK15: 0 | AL15: 0 | AM15: 0 | AN15: 0 | AO15: 0 | AP15: 433598.94 | AQ15: 0 | AR15: 0 | AS15: 1.8199479e+09
B16: {=INDEX(_xlfn.TEXTSPLIT($J16,"/"),3)} -> ECC&0&cPVVE&Ex&Chiller__PumpCtrl | C16: {=INDEX(_xlfn.TEXTSPLIT($J16,"/"),2)} -> CZ10 | D16: =$G$3*H16 -> 139.01931 | F16: {=INDEX(_xlfn.TEXTSPLIT($J16,"/"),4)} -> NE-Chiller-CHWPumpCtrl-Full-Msr | G16: =$P16 -> 0.199597 | H16: =$G$4*G16 -> 198.59902 | J16: runs/CZ10/ECC&0&cPVVE&Ex&Chiller__PumpCtrl/NE-Chiller-CHWPumpCtrl-Full-Msr/instance-out.sql | K16: CZ10 | M16: 38243.21 | N16: 13395.99 | P16: 0.199597 | Q16: 0 | R16: 1058650.7 | S16: 350734.07 | T16: 0 | U16: 936314.72 | V16: 0 | W16: 376587.26 | X16: 303779.41 | Y16: 321293.68 | Z16: 0 | AA16: 0 | AB16: 0 | AC16: 0 | AD16: 0 | AE16: 340678.11 | AF16: 0 | AG16: 0 | AH16: 0 | AI16: 68627.6 | AJ16: 0 | AK16: 0 | AL16: 0 | AM16: 0 | AN16: 0 | AO16: 0 | AP16: 428567.2 | AQ16: 0 | AR16: 0 | AS16: 2.3528832e+09
B17: {=INDEX(_xlfn.TEXTSPLIT($J17,"/"),3)} -> ECC&0&cPVVE&Ex&Chiller__PumpCtrl | C17: {=INDEX(_xlfn.TEXTSPLIT($J17,"/"),2)} -> CZ11 | D17: =$G$3*H17 -> 140.53907 | F17: {=INDEX(_xlfn.TEXTSPLIT($J17,"/"),4)} -> NE-Chiller-CHWPumpCtrl-Full-Msr | G17: =$P17 -> 0.201779 | H17: =$G$4*G17 -> 200.7701 | J17: runs/CZ11/ECC&0&cPVVE&Ex&Chiller__PumpCtrl/NE-Chiller-CHWPumpCtrl-Full-Msr/instance-out.sql | K17: CZ11 | M17: 38661.34 | N17: 13542.45 | P17: 0.201779 | Q17: 0 | R17: 989445.66 | S17: 350734.07 | T17: 0 | U17: 936314.72 | V17: 0 | W17: 415757.44 | X17: 286246.05 | Y17: 294471.4 | Z17: 0 | AA17: 0 | AB17: 0 | AC17: 0 | AD17: 0 | AE17: 449792.58 | AF17: 0 | AG17: 0 | AH17: 0 | AI17: 68627.6 | AJ17: 0 | AK17: 0 | AL17: 0 | AM17: 0 | AN17: 0 | AO17: 0 | AP17: 437501.42 | AQ17: 0 | AR17: 0 | AS17: 2.6826704e+09
B18: {=INDEX(_xlfn.TEXTSPLIT($J18,"/"),3)} -> ECC&0&cPVVE&Ex&Chiller__PumpCtrl | C18: {=INDEX(_xlfn.TEXTSPLIT($J18,"/"),2)} -> CZ12 | D18: =$G$3*H18 -> 137.09279 | F18: {=INDEX(_xlfn.TEXTSPLIT($J18,"/"),4)} -> NE-Chiller-CHWPumpCtrl-Full-Msr | G18: =$P18 -> 0.196831 | H18: =$G$4*G18 -> 195.84685 | J18: runs/CZ12/ECC&0&cPVVE&Ex&Chiller__PumpCtrl/NE-Chiller-CHWPumpCtrl-Full-Msr/instance-out.sql | K18: CZ12 | M18: 37713.24 | N18: 13210.35 | P18: 0.196831 | Q18: 0 | R18: 866223.47 | S18: 350734.07 | T18: 0 | U18: 936314.72 | V18: 0 | W18: 459640.08 | X18: 278377.15 | Y18: 286568.28 | Z18: 0 | AA18: 0 | AB18: 0 | AC18: 0 | AD18: 0 | AE18: 641165.73 | AF18: 0 | AG18: 0 | AH18: 0 | AI18: 68627.6 | AJ18: 0 | AK18: 0 | AL18: 0 | AM18: 0 | AN18: 0 | AO18: 0 | AP18: 450758.13 | AQ18: 0 | AR18: 0 | AS18: 2.5477718e+09
... B294: {=INDEX(_xlfn.TEXTSPLIT($J294,"/"),3)} -> Rt3&0&cPVVE&New&Chiller__PumpCtrl | C294: {=INDEX(_xlfn.TEXTSPLIT($J294,"/"),2)} -> CZ16 | D294: =$G$3*H294 -> 57.968998 | F294: {=INDEX(_xlfn.TEXTSPLIT($J294,"/"),4)} -> NE-Chiller-CHWPumpCtrl-Full-Msr | G294: =$P294 -> 0.083229 | H294: =$G$4*G294 -> 82.812855 | J294: runs/CZ16/Rt3&0&cPVVE&New&Chiller__PumpCtrl/NE-Chiller-CHWPumpCtrl-Full-Msr/instance-out.sql | K294: CZ16 | M294: 15946.91 | N294: 5585.95 | P294: 0.083229 | Q294: 0 | R294: 449048.38 | S294: 394508.4 | T294: 0 | U294: 436518 | V294: 0 | W294: 288004.57 | X294: 72943 | Y294: 67436.65 | Z294: 0 | AA294: 0 | AB294: 0 | AC294: 0 | AD294: 0 | AE294: 578239.32 | AF294: 0 | AG294: 0 | AH294: 0 | AI294: 0 | AJ294: 0 | AK294: 0 | AL294: 0 | AM294: 0 | AN294: 0 | AO294: 0 | AP294: 174059.91 | AQ294: 0 | AR294: 0 | AS294: 1.6365977e+09
B295: {=INDEX(_xlfn.TEXTSPLIT($J295,"/"),3)} -> ECC&0&cPVVE&Ex&Chiller__PumpCtrl | C295: {=INDEX(_xlfn.TEXTSPLIT($J295,"/"),2)} -> CZ01 | D295: =$G$3*H295 -> 97.497463 | F295: {=INDEX(_xlfn.TEXTSPLIT($J295,"/"),4)} -> NE-Chiller-PumpCtrl-Full-Std | G295: =$P295 -> 0.139982 | H295: =$G$4*G295 -> 139.28209 | J295: runs/CZ01/ECC&0&cPVVE&Ex&Chiller__PumpCtrl/NE-Chiller-PumpCtrl-Full-Std/instance-out.sql | K295: CZ01 | L295: 9394.92 | M295: 26820.85 | P295: 0.139982 | Q295: 0 | R295: 306314.87 | S295: 350734.07 | T295: 0 | U295: 936314.72 | V295: 0 | W295: 250366.74 | X295: 219858.82 | Y295: 203288.72 | Z295: 0 | AA295: 0 | AB295: 0 | AC295: 0 | AD295: 0 | AE295: 333355.79 | AF295: 0 | AG295: 0 | AH295: 0 | AI295: 68627.6 | AJ295: 0 | AK295: 0 | AL295: 0 | AM295: 0 | AN295: 0 | AO295: 0 | AP295: 530266 | AQ295: 0 | AR295: 0 | AS295: 1.615349e+09
B296: {=INDEX(_xlfn.TEXTSPLIT($J296,"/"),3)} -> ECC&0&cPVVE&Ex&Chiller__PumpCtrl | C296: {=INDEX(_xlfn.TEXTSPLIT($J296,"/"),2)} -> CZ02 | D296: =$G$3*H296 -> 125.36512 | F296: {=INDEX(_xlfn.TEXTSPLIT($J296,"/"),4)} -> NE-Chiller-PumpCtrl-Full-Std | G296: =$P296 -> 0.179993 | H296: =$G$4*G296 -> 179.09303 | J296: runs/CZ02/ECC&0&cPVVE&Ex&Chiller__PumpCtrl/NE-Chiller-PumpCtrl-Full-Std/instance-out.sql | K296: CZ02 | L296: 12080.31 | M296: 34487.19 | P296: 0.179993 | Q296: 0 | R296: 958849.15 | S296: 350734.07 | T296: 0 | U296: 936314.72 | V296: 0 | W296: 344610.07 | X296: 293045.69 | Y296: 262300.84 | Z296: 0 | AA296: 0 | AB296: 0 | AC296: 0 | AD296: 0 | AE296: 452723.12 | AF296: 0 | AG296: 0 | AH296: 0 | AI296: 68627.6 | AJ296: 0 | AK296: 0 | AL296: 0 | AM296: 0 | AN296: 0 | AO296: 0 | AP296: 486315.51 | AQ296: 0 | AR296: 0 | AS296: 2.712454e+09
B297: {=INDEX(_xlfn.TEXTSPLIT($J297,"/"),3)} -> ECC&0&cPVVE&Ex&Chiller__PumpCtrl | C297: {=INDEX(_xlfn.TEXTSPLIT($J297,"/"),2)} -> CZ03 | D297: =$G$3*H297 -> 117.82969 | F297: {=INDEX(_xlfn.TEXTSPLIT($J297,"/"),4)} -> NE-Chiller-PumpCtrl-Full-Std | G297: =$P297 -> 0.169174 | H297: =$G$4*G297 -> 168.32813 | J297: runs/CZ03/ECC&0&cPVVE&Ex&Chiller__PumpCtrl/NE-Chiller-PumpCtrl-Full-Std/instance-out.sql | K297: CZ03 | L297: 11354.16 | M297: 32414.14 | P297: 0.169174 | Q297: 0 | R297: 729742.33 | S297: 350734.07 | T297: 0 | U297: 936314.72 | V297: 0 | W297: 256142.72 | X297: 291446.92 | Y297: 270195.55 | Z297: 0 | AA297: 0 | AB297: 0 | AC297: 0 | AD297: 0 | AE297: 171260.53 | AF297: 0 | AG297: 0 | AH297: 0 | AI297: 68627.6 | AJ297: 0 | AK297: 0 | AL297: 0 | AM297: 0 | AN297: 0 | AO297: 0 | AP297: 484927.18 | AQ297: 0 | AR297: 0 | AS297: 2.2308378e+09
B298: {=INDEX(_xlfn.TEXTSPLIT($J298,"/"),3)} -> ECC&0&cPVVE&Ex&Chiller__PumpCtrl | C298: {=INDEX(_xlfn.TEXTSPLIT($J298,"/"),2)} -> CZ04 | D298: =$G$3*H298 -> 126.93852 | F298: {=INDEX(_xlfn.TEXTSPLIT($J298,"/"),4)} -> NE-Chiller-PumpCtrl-Full-Std | G298: =$P298 -> 0.182252 | H298: =$G$4*G298 -> 181.34074 | J298: runs/CZ04/ECC&0&cPVVE&Ex&Chiller__PumpCtrl/NE-Chiller-PumpCtrl-Full-Std/instance-out.sql | K298: CZ04 | L298: 12231.88 | M298: 34919.87 | P298: 0.182252 | Q298: 0 | R298: 1052355.1 | S298: 350734.07 | T298: 0 | U298: 936314.72 | V298: 0 | W298: 302795.31 | X298: 314908.24 | Y298: 293876.53 | Z298: 0 | AA298: 0 | AB298: 0 | AC298: 0 | AD298: 0 | AE298: 241280.04 | AF298: 0 | AG298: 0 | AH298: 0 | AI298: 68627.6 | AJ298: 0 | AK298: 0 | AL298: 0 | AM298: 0 | AN298: 0 | AO298: 0 | AP298: 467599.86 | AQ298: 0 | AR298: 0 | AS298: 2.6407646e+09
